Workbook

Sheet Temas desarrollados
B2: Plan de Clases
A3: 45716 | B3: Presentación e integración
A4: 45723 | B4: Introducción
A5: 45730 | B5: La persona, Concepto
A6: 45737 | B6: La Persona, Desarrollo
A7: 45744 | B7: Reposo Médico del Docente
A8: 45751 | B8: La Moral
A9: 45758 | B9: La Ética
A10: 45765 | B10: Semana Santa - Feriado
A11: 45772 | B11: =+Asistencia!L2 -> Repaso
A12: 45779
A13: 45786 | B13: Sin Clases, Sin energia Electrica
A14: 45793 | B14: Trabajo emblematico: Sobre Hábitos Saludable: Elaboración del Uso del Tiempo
A15: 45800 | B15: Trabajo emblematico: Sobre Hábitos Saludable
A16: 45807 | B16: Examen
A17: 45814 | B17: Trabajo emblematico: Sobre Hábitos Saludable
A18: 45821
A19: 45828
A20: 45835
A21: 45842
A22: 45849
A23: 45856
A24: 45863

Sheet Asistencia
B1: Asistencia | D1: 45716 | E1: 45723 | F1: 45730 | G1: 45737 | H1: 45744 | I1: 45751 | J1: 45758 | K1: 45765 | L1: 45772 | M1: 45779 | N1: 45786 | O1: 45793 | P1: 45800 | Q1: 45807 | R1: 45814 | S1: 45821 | T1: 45828 | U1: 45835 | V1: 45842 | W1: 45849 | X1: 45856 | Y1: 45863 | Z1: Firmas
A2: Nombre y Apellido / Desarrollo de la Unidad | D2: Presentación e integración | E2: =+'Temas desarrollados'!B4 -> Introducción | F2: La Persona Desarrollo | G2: La Persona - Desarrollo | H2: S/D | I2: La Moral | J2: =+'Temas desarrollados'!B9 -> La Ética | K2: Feriado | L2: Repaso | M2: La Familia | N2: Sin Clases, Sin energia Electrica | O2: Prog. Emb. Habitos | P2: Prog. Emb. Habitos | Q2: =+'Temas desarrollados'!B16 -> Examen | R2: =+'Temas desarrollados'!B17 -> Trabajo emblematico: Sobre Hábitos Saludable | S2: =+'Temas desarrollados'!B18 -> 0 | T2: =+'Temas desarrollados'!B19 -> 0 | U2: =+'Temas desarrollados'!B20 -> 0
A3: -1 | B3: ARCE CABALLERO,NAHIARA NOEMI | C3: 7344430 | D3: PF | E3: P | F3: PF | G3: PF | H3: P | I3: PF | J3: FP | K3: FN | L3: P | M3: PF | N3: SC | O3: PF | P3: PF | U3: P | Z3: =+COUNTIF(D3:Y3,"PF")+COUNTIF(D3:Y3,"AF") -> 7 | AA3: =7-Z3 -> 0
A4: -2 | B4: ARCE CONTESSI,GUADALUPE MARIA LUJAN | C4: 7503128 | D4: PF | E4: P | F4: pf | G4: P | H4: P | I4: PF | J4: pf | K4: F | L4: P | M4: PF | N4: SC | O4: PF | P4: PF | U4: P | Z4: =+COUNTIF(D4:Y4,"PF")+COUNTIF(D4:Y4,"AF") -> 7 | AA4: =7-Z4 -> 0
A5: -3 | B5: AYALA MAIDANA,ALMA ISABELLA | C5: 7343210 | D5: PF | E5: P | F5: PF | G5: P | H5: PF | I5: PF | J5: PF | K5: F | L5: P | M5: PF | N5: SC | O5: PF | P5: A | U5: P | Z5: =+COUNTIF(D5:Y5,"PF")+COUNTIF(D5:Y5,"AF") -> 7 | AA5: =7-Z5 -> 0
A6: -4 | B6: BARRETO AYALA,GUADALUPE MABEL | C6: 7474276 | D6: PF | E6: P | F6: pf | G6: P | H6: P | I6: pf | J6: pf | K6: F | L6: P | M6: PF | N6: SC | O6: PF | P6: pf | U6: P | Z6: =+COUNTIF(D6:Y6,"PF")+COUNTIF(D6:Y6,"AF") -> 7 | AA6: =7-Z6 -> 0
A7: -5 | B7: BARRIOS MONGES,LUIS JESUS | C7: 7958599 | D7: PF | E7: P | F7: pf | G7: pf | H7: P | I7: pf | J7: pf | K7: F | L7: P | M7: P | N7: SC | O7: PF | P7: pf | U7: P | Z7: =+COUNTIF(D7:Y7,"PF")+COUNTIF(D7:Y7,"AF") -> 7 | AA7: =7-Z7 -> 0
A8: -6 | B8: BENITEZ GIMENEZ,LUANA ISABEL | C8: 8101499 | D8: PF | E8: P | F8: pf | G8: pf | H8: P | I8: PF | J8: PF | K8: F | L8: P | M8: P | N8: SC | O8: PF | P8: pf | U8: P | Z8: =+COUNTIF(D8:Y8,"PF")+COUNTIF(D8:Y8,"AF") -> 7 | AA8: =7-Z8 -> 0
A9: -7 | B9: BOGARIN ZORIA,TAMARY ANGELICA | C9: 7651970 | D9: PF | E9: P | F9: PF | G9: P | H9: P | I9: PF | J9: PF | K9: F | L9: P | M9: PF | N9: SC | O9: PF | P9: A | U9: P | Z9: =+COUNTIF(D9:Y9,"PF")+COUNTIF(D9:Y9,"AF") -> 6 | AA9: =7-Z9 -> 1
A10: -8 | B10: CABALLERO DIAZ,CARLOS RODRIGO | C10: 7222581 | D10: PF | E10: P | F10: PF | G10: P | H10: P | I10: pf | J10: pf | K10: F | L10: P | M10: PF | N10: SC | O10: PF | P10: PF | U10: P | Z10: =+COUNTIF(D10:Y10,"PF")+COUNTIF(D10:Y10,"AF") -> 7 | AA10: =7-Z10 -> 0
A11: -9 | B11: CACERES ROMAN,THAIS VICTORIA | C11: 7357774 | D11: PF | E11: P | F11: PF | G11: P | H11: P | I11: PF | J11: PF | K11: F | L11: P | M11: PF | N11: SC | O11: PF | P11: AF | U11: P | Z11: =+COUNTIF(D11:Y11,"PF")+COUNTIF(D11:Y11,"AF") -> 7 | AA11: =7-Z11 -> 0
A12: -10 | B12: CONTESSI PEREIRA,PAULA ARIANNA | C12: 7342752 | D12: PF | E12: P | F12: pf | G12: P | H12: P | I12: pf | J12: pf | K12: F | L12: P | M12: P | N12: SC | O12: PF | P12: PF | U12: P | Z12: =+COUNTIF(D12:Y12,"PF")+COUNTIF(D12:Y12,"AF") -> 6 | AA12: =7-Z12 -> 1
A13: -11 | B13: ESTIGARRIBIA ESTIGARRIBIA,BASTTIAN JOSUE | C13: 8375944 | D13: PF | E13: P | F13: PF | G13: PF | H13: PF | I13: PF | J13: PF | K13: F | L13: P | M13: PF | N13: SC | O13: PF | P13: PF | U13: A | Z13: 7 | AA13: 0
A14: -12 | B14: FERNANDEZ ARCE,IVONNE VIRGINIA | C14: 7552480 | D14: PF | E14: P | F14: PF | G14: P | H14: P | I14: PF | J14: PF | K14: F | L14: P | M14: PF | N14: SC | O14: PF | P14: PF | Z14: =+COUNTIF(D14:Y14,"PF")+COUNTIF(D14:Y14,"AF") -> 7 | AA14: =7-Z14 -> 0
A15: -13 | B15: FERNANDEZ TRINIDAD,EMILIA ARAMI | C15: 7227419 | D15: PF | E15: P | F15: A | G15: PF | H15: P | I15: PF | J15: PF | K15: F | L15: A | M15: P | N15: SC | O15: PF | P15: PF | U15: p | Z15: =+COUNTIF(D15:Y15,"PF")+COUNTIF(D15:Y15,"AF") -> 6 | AA15: =7-Z15 -> 1
A16: -14 | B16: FLORENTIN LEDEZMA,TAMARA NOEMI | C16: 7202209 | D16: PF | E16: P | F16: PF | G16: P | H16: P | I16: PF | J16: P | K16: F | L16: P | M16: P | N16: SC | O16: PF | P16: P | U16: p | Z16: =+COUNTIF(D16:Y16,"PF")+COUNTIF(D16:Y16,"AF") -> 4 | AA16: =7-Z16 -> 3
A17: -15 | B17: FLORENTIN MARTINEZ,AYLEN PAZCAL | C17: 7265455 | D17: PF | E17: P | F17: PF | G17: PF | H17: P | I17: PF | J17: PF | K17: F | L17: P | M17: PF | N17: SC | O17: PF | P17: A | U17: p | Z17: =+COUNTIF(D17:Y17,"PF")+COUNTIF(D17:Y17,"AF") -> 7 | AA17: =7-Z17 -> 0
A18: -16 | B18: FRANCO ARCE,PAULA YELENNA | C18: 7429371 | D18: PF | E18: P | F18: PF | G18: P | H18: P | I18: PF | J18: PF | K18: F | L18: P | M18: PF | N18: SC | O18: PF | P18: PF | U18: p | Z18: =+COUNTIF(D18:Y18,"PF")+COUNTIF(D18:Y18,"AF") -> 7 | AA18: =7-Z18 -> 0
A19: -17 | B19: GAONA BAEZ,JEANELLY GUADALUPE | C19: 7444777 | D19: PF | E19: P | F19: PF | G19: P | H19: P | I19: PF | J19: P | K19: F | L19: P | M19: PF | N19: SC | O19: PF | P19: PF | Q19: PF | U19: p | Z19: =+COUNTIF(D19:Y19,"PF")+COUNTIF(D19:Y19,"AF") -> 7 | AA19: =7-Z19 -> 0
A20: -18 | B20: GARCIA VIANCONI,LAUTARO RADAMEL | C20: 7444631 | D20: PF | E20: P | F20: AF | G20: A | H20: A | I20: PF | J20: PF | K20: F | L20: P | M20: P | N20: SC | O20: PF | P20: P | U20: p | Z20: =+COUNTIF(D20:Y20,"PF")+COUNTIF(D20:Y20,"AF") -> 5 | AA20: =7-Z20 -> 2
A21: -19 | B21: GIMENEZ GALEANO,SANTIAGO MIQUEAS | C21: 7514145 | D21: PF | E21: P | F21: PF | G21: P | H21: P | I21: PF | J21: PF | K21: F | L21: P | M21: PF | N21: SC | O21: PF | P21: PF | U21: p | Z21: =+COUNTIF(D21:Y21,"PF")+COUNTIF(D21:Y21,"AF") -> 7 | AA21: =7-Z21 -> 0
A22: -20 | B22: GIRETT PEREIRA,SANTIAGO JAVIER | C22: 7386167 | D22: PF | E22: P | F22: PF | G22: P | H22: P | I22: PF | J22: PF | K22: F | L22: P | M22: P | N22: SC | O22: PF | P22: P | U22: A | Z22: =+COUNTIF(D22:Y22,"PF")+COUNTIF(D22:Y22,"AF") -> 5 | AA22: =7-Z22 -> 2
A23: -21 | B23: GOMEZ BENITEZ,FREDY ANTONIO | C23: 8036254 | D23: PF | E23: P | F23: AF | G23: P | H23: PF | I23: PF | J23: PF | K23: F | L23: P | M23: P | N23: SC | O23: PF | P23: P | U23: P | Z23: =+COUNTIF(D23:Y23,"PF")+COUNTIF(D23:Y23,"AF") -> 6 | AA23: =7-Z23 -> 1
A24: -22 | B24: GONZALEZ LOPEZ,BETHANIA MONSERRAT | C24: 7805242 | D24: PF | E24: P | F24: PF | G24: P | H24: P | I24: PF | J24: PF | K24: F | L24: P | M24: P | N24: SC | O24: PF | P24: P | U24: A | Z24: =+COUNTIF(D24:Y24,"PF")+COUNTIF(D24:Y24,"AF") -> 5 | AA24: =7-Z24 -> 2
A25: -23 | B25: IRALA PINIENTA,SHEYLA YAMILET | C25: 7167263 | D25: PF | E25: P | F25: PF | G25: P | H25: P | I25: PF | J25: PF | K25: F | L25: P | M25: PF | N25: SC | O25: PF | P25: PF | Z25: =+COUNTIF(D25:Y25,"PF")+COUNTIF(D25:Y25,"AF") -> 7 | AA25: =7-Z25 -> 0
A26: -24 | B26: JARA BERNAL,BRAHIAN LIONEL | C26: 7594625 | D26: PF | E26: AF | F26: PF | G26: P | H26: P | I26: PF | J26: PF | K26: F | L26: P | M26: PF | N26: SC | O26: PF | P26: P | Z26: =+COUNTIF(D26:Y26,"PF")+COUNTIF(D26:Y26,"AF") -> 7 | AA26: =7-Z26 -> 0
A27: -25 | B27: MARTINEZ ROJAS,JOSIAS ARNALDO | C27: 7240549 | D27: PF | E27: P | F27: PF | G27: P | H27: P | I27: PF | J27: PF | K27: F | L27: A | M27: P | N27: SC | O27: PF | P27: PF | U27: A | Z27: =+COUNTIF(D27:Y27,"PF")+COUNTIF(D27:Y27,"AF") -> 6 | AA27: =7-Z27 -> 1
A28: -26 | B28: NOTARIO CABRAL,KARINA LUJAN | C28: 7398696 | D28: PF | E28: A | F28: PF | G28: PF | H28: P | I28: PF | J28: PF | K28: F | L28: A | M28: P | N28: SC | O28: PF | P28: PF | U28: P | Z28: =+COUNTIF(D28:Y28,"PF")+COUNTIF(D28:Y28,"AF") -> 7 | AA28: =7-Z28 -> 0
A29: -27 | B29: NUÑEZ JARA,MATHIAS ISMAEL | C29: 7533418 | D29: PF | E29: P | F29: PF | G29: A | H29: P | I29: PF | J29: PF | K29: F | L29: A | M29: P | N29: SC | O29: PF | P29: PF | U29: P | Z29: =+COUNTIF(D29:Y29,"PF")+COUNTIF(D29:Y29,"AF") -> 6 | AA29: =7-Z29 -> 1
A30: -28 | B30: PAEZ CATTEBEKE,FIORELLA MONSERRAT | C30: 7335885 | D30: PF | E30: P | F30: AF | G30: PF | H30: P | I30: PF | J30: PF | K30: F | L30: P | M30: P | N30: SC | O30: PF | P30: PF | U30: P | Z30: =+COUNTIF(D30:Y30,"PF")+COUNTIF(D30:Y30,"AF") -> 7 | AA30: =7-Z30 -> 0
A31: -29 | B31: PARDO ALUB,SAMIRA | C31: 7504518 | D31: PF | E31: P | F31: PF | G31: PF | H31: P | I31: PF | J31: PF | K31: F | L31: P | M31: P | N31: SC | O31: PF | P31: P | U31: P | Z31: =+COUNTIF(D31:Y31,"PF")+COUNTIF(D31:Y31,"AF") -> 6 | AA31: =7-Z31 -> 1
A32: -30 | B32: PINHO MILLAN,JONATHAN JOSIAS | C32: 7318166 | D32: PF | E32: P | F32: PF | G32: P | H32: P | I32: PF | J32: PF | K32: F | L32: A | M32: P | N32: SC | O32: PF | P32: P | U32: AJ | Z32: =+COUNTIF(D32:Y32,"PF")+COUNTIF(D32:Y32,"AF") -> 5 | AA32: =7-Z32 -> 2
A33: -31 | B33: QUIÑONEZ CARDOZO,LUCERO ABYGAIL | C33: 7384033 | D33: PF | E33: P | F33: A | G33: A | H33: P | I33: PF | J33: PF | K33: F | L33: P | M33: P | N33: SC | O33: PF | P33: PF | U33: A | Z33: =+COUNTIF(D33:Y33,"PF")+COUNTIF(D33:Y33,"AF") -> 5 | AA33: =7-Z33 -> 2
A34: -32 | B34: RAMIREZ PAEZ,EIKER DAMIAN | C34: 7324122 | D34: PF | E34: A | F34: PF | G34: A | H34: P | I34: PF | J34: PF | K34: F | L34: P | M34: P | N34: SC | O34: PF | P34: P | U34: A | Z34: =+COUNTIF(D34:Y34,"PF")+COUNTIF(D34:Y34,"AF") -> 5 | AA34: =7-Z34 -> 2
A35: -33 | B35: RECALDE CANDIA,ALEXIS TOBIAS | C35: 7342346 | D35: PF | E35: P | F35: PF | G35: P | H35: P | I35: PF | J35: PF | K35: F | L35: P | M35: P | N35: SC | O35: PF | P35: P | U35: A | Z35: =+COUNTIF(D35:Y35,"PF")+COUNTIF(D35:Y35,"AF") -> 5 | AA35: =7-Z35 -> 2
A36: -34 | B36: ROA NUÑEZ,VANIA AILYN | C36: 7367983 | D36: PF | E36: P | F36: PF | G36: PF | H36: P | I36: PF | J36: PF | K36: F | L36: P | M36: PF | N36: SC | O36: PF | P36: P | U36: P | Z36: =+COUNTIF(D36:Y36,"PF")+COUNTIF(D36:Y36,"AF") -> 7 | AA36: =7-Z36 -> 0
A37: -35 | B37: ROJAS FRANCO,HANNY MICAL | C37: 7272130 | D37: PF | E37: P | F37: PF | G37: P | H37: PF | I37: PF | J37: PF | K37: F | L37: P | M37: P | N37: SC | O37: PF | P37: PF | U37: P | Z37: =+COUNTIF(D37:Y37,"PF")+COUNTIF(D37:Y37,"AF") -> 7 | AA37: =7-Z37 -> 0
A38: -36 | B38: ROMERO PRIETO,HEIDY JIANNINA | C38: 7443701 | D38: PF | E38: P | F38: PF | G38: P | H38: PF | I38: PF | J38: PF | K38: F | L38: A | M38: P | N38: SC | O38: PF | P38: P | U38: A | Z38: =+COUNTIF(D38:Y38,"PF")+COUNTIF(D38:Y38,"AF") -> 6 | AA38: =7-Z38 -> 1
... A42: -40 | B42: VERA ALCARAZ, LIZZIE CAROLINA | C42: 7377595 | D42: PF | E42: P | F42: PF | G42: P | H42: P | I42: PF | J42: PF | K42: F | L42: P | M42: P | N42: SC | O42: PF | P42: P | U42: A | Z42: =+COUNTIF(D42:Y42,"PF")+COUNTIF(D42:Y42,"AF") -> 5 | AA42: =7-Z42 -> 2

Sheet Indicadores Actitudinal
D2: Total | E2: Nivel de atención y concentración: Medir cuánto tiempo puede mantenerse atenta y enfocada en las actividades dentro del aula, observando si se distrae con facilidad o interrumpe la clase con movimientos constantes. | F2: Cumplimiento de normas y reglas del aula: Evaluar si respeta las reglas establecidas, como permanecer en su lugar, no salir sin permiso y participar en las tareas asignadas. | G2: Entrega los Trabajos a tiempo
A3: 1 | B3: ARCE CABALLERO,NAHIARA NOEMI | C3: 7344430 | D3: =+SUM(E3:H3) -> 3 | E3: 1 | F3: 1 | G3: 1
A4: 2 | B4: ARCE CONTESSI,GUADALUPE MARIA LUJAN | C4: 7503128 | D4: =+SUM(E4:H4) -> 3 | E4: 1 | F4: 1 | G4: 1
A5: 3 | B5: AYALA MAIDANA,ALMA ISABELLA | C5: 7343210 | D5: =+SUM(E5:H5) -> 3 | E5: 1 | F5: 1 | G5: 1
A6: 4 | B6: BARRETO AYALA,GUADALUPE MABEL | C6: 7474276 | D6: =+SUM(E6:H6) -> 3 | E6: 1 | F6: 1 | G6: 1
A7: 5 | B7: BARRIOS MONGES,LUIS JESUS | C7: 7958599 | D7: =+SUM(E7:H7) -> 3 | E7: 1 | F7: 1 | G7: 1
A8: 6 | B8: BENITEZ GIMENEZ,LUANA ISABEL | C8: 8101499 | D8: =+SUM(E8:H8) -> 3 | E8: 1 | F8: 1 | G8: 1
A9: 7 | B9: BOGARIN ZORIA,TAMARY ANGELICA | C9: 7651970 | D9: =+SUM(E9:H9) -> 3 | E9: 1 | F9: 1 | G9: 1
A10: 8 | B10: CABALLERO DIAZ,CARLOS RODRIGO | C10: 7222581 | D10: =+SUM(E10:H10) -> 3 | E10: 1 | F10: 1 | G10: 1
A11: 9 | B11: CACERES ROMAN,THAIS VICTORIA | C11: 7357774 | D11: =+SUM(E11:H11) -> 3 | E11: 1 | F11: 1 | G11: 1
A12: 10 | B12: CONTESSI PEREIRA,PAULA ARIANNA | C12: 7342752 | D12: =+SUM(E12:H12) -> 3 | E12: 1 | F12: 1 | G12: 1
A13: 11 | B13: ESTIGARRIBIA ESTIGARRIBIA,BASTTIAN JOSUE | C13: 8375944 | D13: =+SUM(E13:H13) -> 3 | E13: 1 | F13: 1 | G13: 1
A14: 12 | B14: FERNANDEZ ARCE,IVONNE VIRGINIA | C14: 7552480 | D14: =+SUM(E14:H14) -> 3 | E14: 1 | F14: 1 | G14: 1
A15: 13 | B15: FERNANDEZ TRINIDAD,EMILIA ARAMI | C15: 7227419 | D15: =+SUM(E15:H15) -> 2 | F15: 1 | G15: 1
A16: 14 | B16: FLORENTIN LEDEZMA,TAMARA NOEMI | C16: 7202209 | D16: =+SUM(E16:H16) -> 3 | E16: 1 | F16: 1 | G16: 1
A17: 15 | B17: FLORENTIN MARTINEZ,AYLEN PAZCAL | C17: 7265455 | D17: =+SUM(E17:H17) -> 3 | E17: 1 | F17: 1 | G17: 1
A18: 16 | B18: FRANCO ARCE,PAULA YELENNA | C18: 7429371 | D18: =+SUM(E18:H18) -> 3 | E18: 1 | F18: 1 | G18: 1
A19: 17 | B19: GAONA BAEZ,JEANELLY GUADALUPE | C19: 7444777 | D19: =+SUM(E19:H19) -> 3 | E19: 1 | F19: 1 | G19: 1
A20: 18 | B20: GARCIA VIANCONI,LAUTARO RADAMEL | C20: 7444631 | D20: =+SUM(E20:H20) -> 2 | F20: 1 | G20: 1
A21: 19 | B21: GIMENEZ GALEANO,SANTIAGO MIQUEAS | C21: 7514145 | D21: =+SUM(E21:H21) -> 3 | E21: 1 | F21: 1 | G21: 1
A22: 20 | B22: GIRETT PEREIRA,SANTIAGO JAVIER | C22: 7386167 | D22: =+SUM(E22:H22) -> 3 | E22: 1 | F22: 1 | G22: 1
A23: 21 | B23: GOMEZ BENITEZ,FREDY ANTONIO | C23: 8036254 | D23: =+SUM(E23:H23) -> 2 | F23: 1 | G23: 1
A24: 22 | B24: GONZALEZ LOPEZ,BETHANIA MONSERRAT | C24: 7805242 | D24: =+SUM(E24:H24) -> 3 | E24: 1 | F24: 1 | G24: 1
A25: 23 | B25: IRALA PINIENTA,SHEYLA YAMILET | C25: 7167263 | D25: =+SUM(E25:H25) -> 3 | E25: 1 | F25: 1 | G25: 1
A26: 24 | B26: JARA BERNAL,BRAHIAN LIONEL | C26: 7594625 | D26: =+SUM(E26:H26) -> 3 | E26: 1 | F26: 1 | G26: 1
A27: 25 | B27: MARTINEZ ROJAS,JOSIAS ARNALDO | C27: 7240549 | D27: =+SUM(E27:H27) -> 3 | E27: 1 | F27: 1 | G27: 1
A28: 26 | B28: NOTARIO CABRAL,KARINA LUJAN | C28: 7398696 | D28: =+SUM(E28:H28) -> 3 | E28: 1 | F28: 1 | G28: 1
A29: 27 | B29: NUÑEZ JARA,MATHIAS ISMAEL | C29: 7533418 | D29: =+SUM(E29:H29) -> 3 | E29: 1 | F29: 1 | G29: 1
A30: 28 | B30: PAEZ CATTEBEKE,FIORELLA MONSERRAT | C30: 7335885 | D30: =+SUM(E30:H30) -> 3 | E30: 1 | F30: 1 | G30: 1
A31: 29 | B31: PARDO ALUB,SAMIRA | C31: 7504518 | D31: =+SUM(E31:H31) -> 3 | E31: 1 | F31: 1 | G31: 1
A32: 30 | B32: PINHO MILLAN,JONATHAN JOSIAS | C32: 7318166 | D32: =+SUM(E32:H32) -> 3 | E32: 1 | F32: 1 | G32: 1
A33: 31 | B33: QUIÑONEZ CARDOZO,LUCERO ABYGAIL | C33: 7384033 | D33: =+SUM(E33:H33) -> 2 | F33: 1 | G33: 1
A34: 32 | B34: RAMIREZ PAEZ,EIKER DAMIAN | C34: 7324122 | D34: =+SUM(E34:H34) -> 3 | E34: 1 | F34: 1 | G34: 1
A35: 33 | B35: RECALDE CANDIA,ALEXIS TOBIAS | C35: 7342346 | D35: =+SUM(E35:H35) -> 3 | E35: 1 | F35: 1 | G35: 1
A36: 34 | B36: ROA NUÑEZ,VANIA AILYN | C36: 7367983 | D36: =+SUM(E36:H36) -> 3 | E36: 1 | F36: 1 | G36: 1
A37: 35 | B37: ROJAS FRANCO,HANNY MICAL | C37: 7272130
A38: 36 | B38: ROMERO PRIETO,HEIDY JIANNINA | C38: 7443701 | D38: =+SUM(E38:H38) -> 3 | E38: 1 | F38: 1 | G38: 1
A39: 37 | B39: SALCEDO AYALA,CHRISTOPHER RODRIGO | C39: 7542562 | D39: =+SUM(E39:H39) -> 3 | E39: 1 | F39: 1 | G39: 1
A40: 38 | B40: SAMANIEGO ROJAS,ALEX DAVID | C40: 8000217 | D40: =+SUM(E40:H40) -> 3 | E40: 1 | F40: 1 | G40: 1
A41: 39 | B41: SILVA GARCETE,FREDY MISAEL | C41: 7500428 | D41: =+SUM(E41:H41) -> 3 | E41: 1 | F41: 1 | G41: 1
...

Sheet La persona
K1: 45730
D2: Total | E2: Identifica los principios ética – moral. | F2: Diferencia entre moral y moralidad. | G2: Valora su conocimiento sobre moralidad social. | H2: Reflexiona sobre las normas morales. | I2: Identifica las épocas y cultos. | J2: Valora sus conocimientos. | K2: La Persona Desarrollo
A3: 1 | B3: ARCE CABALLERO,NAHIARA NOEMI | C3: 7344430 | D3: =+SUM(E3:J3) -> 6 | E3: 1 | F3: 1 | G3: 1 | H3: 1 | I3: 1 | J3: 1 | K3: PF
A4: 2 | B4: ARCE CONTESSI,GUADALUPE MARIA LUJAN | C4: 7503128 | D4: =+SUM(E4:J4) -> 6 | E4: 1 | F4: 1 | G4: 1 | H4: 1 | I4: 1 | J4: 1 | K4: PF
A5: 3 | B5: AYALA MAIDANA,ALMA ISABELLA | C5: 7343210 | D5: =+SUM(E5:J5) -> 6 | E5: 1 | F5: 1 | G5: 1 | H5: 1 | I5: 1 | J5: 1 | K5: P
A6: 4 | B6: BARRETO AYALA,GUADALUPE MABEL | C6: 7474276 | D6: =+SUM(E6:J6) -> 6 | E6: 1 | F6: 1 | G6: 1 | H6: 1 | I6: 1 | J6: 1 | K6: PF
A7: 5 | B7: BARRIOS MONGES,LUIS JESUS | C7: 7958599 | D7: =+SUM(E7:J7) -> 6 | E7: 1 | F7: 1 | G7: 1 | H7: 1 | I7: 1 | J7: 1 | K7: PF
A8: 6 | B8: BENITEZ GIMENEZ,LUANA ISABEL | C8: 8101499 | D8: =+SUM(E8:J8) -> 6 | E8: 1 | F8: 1 | G8: 1 | H8: 1 | I8: 1 | J8: 1 | K8: PF
A9: 7 | B9: BOGARIN ZORIA,TAMARY ANGELICA | C9: 7651970 | D9: =+SUM(E9:J9) -> 6 | E9: 1 | F9: 1 | G9: 1 | H9: 1 | I9: 1 | J9: 1 | K9: P
A10: 8 | B10: CABALLERO DIAZ,CARLOS RODRIGO | C10: 7222581 | D10: =+SUM(E10:J10) -> 6 | E10: 1 | F10: 1 | G10: 1 | H10: 1 | I10: 1 | J10: 1 | K10: PF
A11: 9 | B11: CACERES ROMAN,THAIS VICTORIA | C11: 7357774 | D11: =+SUM(E11:J11) -> 6 | E11: 1 | F11: 1 | G11: 1 | H11: 1 | I11: 1 | J11: 1 | K11: P
A12: 10 | B12: CONTESSI PEREIRA,PAULA ARIANNA | C12: 7342752 | D12: =+SUM(E12:J12) -> 6 | E12: 1 | F12: 1 | G12: 1 | H12: 1 | I12: 1 | J12: 1 | K12: PF
A13: 11 | B13: ESTIGARRIBIA ESTIGARRIBIA,BASTTIAN JOSUE | C13: 8375944 | D13: =+SUM(E13:J13) -> 6 | E13: 1 | F13: 1 | G13: 1 | H13: 1 | I13: 1 | J13: 1 | K13: PF
A14: 12 | B14: FERNANDEZ ARCE,IVONNE VIRGINIA | C14: 7552480 | D14: =+SUM(E14:J14) -> 6 | E14: 1 | F14: 1 | G14: 1 | H14: 1 | I14: 1 | J14: 1 | K14: PF
A15: 13 | B15: FERNANDEZ TRINIDAD,EMILIA ARAMI | C15: 7227419 | D15: =+SUM(E15:J15) -> 5 | F15: 1 | G15: 1 | H15: 1 | I15: 1 | J15: 1 | K15: A
A16: 14 | B16: FLORENTIN LEDEZMA,TAMARA NOEMI | C16: 7202209 | D16: =+SUM(E16:J16) -> 6 | E16: 1 | F16: 1 | G16: 1 | H16: 1 | I16: 1 | J16: 1 | K16: P
A17: 15 | B17: FLORENTIN MARTINEZ,AYLEN PAZCAL | C17: 7265455 | D17: =+SUM(E17:J17) -> 6 | E17: 1 | F17: 1 | G17: 1 | H17: 1 | I17: 1 | J17: 1 | K17: P
A18: 16 | B18: FRANCO ARCE,PAULA YELENNA | C18: 7429371 | D18: =+SUM(E18:J18) -> 6 | E18: 1 | F18: 1 | G18: 1 | H18: 1 | I18: 1 | J18: 1 | K18: PF
A19: 17 | B19: GAONA BAEZ,JEANELLY GUADALUPE | C19: 7444777 | D19: =+SUM(E19:J19) -> 6 | E19: 1 | F19: 1 | G19: 1 | H19: 1 | I19: 1 | J19: 1 | K19: P
A20: 18 | B20: GARCIA VIANCONI,LAUTARO RADAMEL | C20: 7444631 | D20: =+SUM(E20:J20) -> 5 | F20: 1 | G20: 1 | H20: 1 | I20: 1 | J20: 1 | K20: A
A21: 19 | B21: GIMENEZ GALEANO,SANTIAGO MIQUEAS | C21: 7514145 | D21: =+SUM(E21:J21) -> 6 | E21: 1 | F21: 1 | G21: 1 | H21: 1 | I21: 1 | J21: 1 | K21: P
A22: 20 | B22: GIRETT PEREIRA,SANTIAGO JAVIER | C22: 7386167 | D22: =+SUM(E22:J22) -> 6 | E22: 1 | F22: 1 | G22: 1 | H22: 1 | I22: 1 | J22: 1 | K22: P
A23: 21 | B23: GOMEZ BENITEZ,FREDY ANTONIO | C23: 8036254 | D23: =+SUM(E23:J23) -> 5 | F23: 1 | G23: 1 | H23: 1 | I23: 1 | J23: 1 | K23: A
A24: 22 | B24: GONZALEZ LOPEZ,BETHANIA MONSERRAT | C24: 7805242 | D24: =+SUM(E24:J24) -> 6 | E24: 1 | F24: 1 | G24: 1 | H24: 1 | I24: 1 | J24: 1 | K24: P
A25: 23 | B25: IRALA PINIENTA,SHEYLA YAMILET | C25: 7167263 | D25: =+SUM(E25:J25) -> 6 | E25: 1 | F25: 1 | G25: 1 | H25: 1 | I25: 1 | J25: 1 | K25: P
A26: 24 | B26: JARA BERNAL,BRAHIAN LIONEL | C26: 7594625 | D26: =+SUM(E26:J26) -> 6 | E26: 1 | F26: 1 | G26: 1 | H26: 1 | I26: 1 | J26: 1 | K26: P
A27: 25 | B27: MARTINEZ ROJAS,JOSIAS ARNALDO | C27: 7240549 | D27: =+SUM(E27:J27) -> 6 | E27: 1 | F27: 1 | G27: 1 | H27: 1 | I27: 1 | J27: 1 | K27: P
A28: 26 | B28: NOTARIO CABRAL,KARINA LUJAN | C28: 7398696 | D28: =+SUM(E28:J28) -> 6 | E28: 1 | F28: 1 | G28: 1 | H28: 1 | I28: 1 | J28: 1 | K28: P
A29: 27 | B29: NUÑEZ JARA,MATHIAS ISMAEL | C29: 7533418 | D29: =+SUM(E29:J29) -> 6 | E29: 1 | F29: 1 | G29: 1 | H29: 1 | I29: 1 | J29: 1 | K29: PF
A30: 28 | B30: PAEZ CATTEBEKE,FIORELLA MONSERRAT | C30: 7335885 | D30: =+SUM(E30:J30) -> 6 | E30: 1 | F30: 1 | G30: 1 | H30: 1 | I30: 1 | J30: 1 | K30: AF
A31: 29 | B31: PARDO ALUB,SAMIRA | C31: 7504518 | D31: =+SUM(E31:J31) -> 6 | E31: 1 | F31: 1 | G31: 1 | H31: 1 | I31: 1 | J31: 1 | K31: P
A32: 30 | B32: PINHO MILLAN,JONATHAN JOSIAS | C32: 7318166 | D32: =+SUM(E32:J32) -> 6 | E32: 1 | F32: 1 | G32: 1 | H32: 1 | I32: 1 | J32: 1 | K32: P
A33: 31 | B33: QUIÑONEZ CARDOZO,LUCERO ABYGAIL | C33: 7384033 | D33: =+SUM(E33:J33) -> 5 | F33: 1 | G33: 1 | H33: 1 | I33: 1 | J33: 1 | K33: A
A34: 32 | B34: RAMIREZ PAEZ,EIKER DAMIAN | C34: 7324122 | D34: =+SUM(E34:J34) -> 6 | E34: 1 | F34: 1 | G34: 1 | H34: 1 | I34: 1 | J34: 1 | K34: P
A35: 33 | B35: RECALDE CANDIA,ALEXIS TOBIAS | C35: 7342346 | D35: =+SUM(E35:J35) -> 6 | E35: 1 | F35: 1 | G35: 1 | H35: 1 | I35: 1 | J35: 1 | K35: P
A36: 34 | B36: ROA NUÑEZ,VANIA AILYN | C36: 7367983 | D36: =+SUM(E36:J36) -> 6 | E36: 1 | F36: 1 | G36: 1 | H36: 1 | I36: 1 | J36: 1 | K36: P
A37: 35 | B37: ROJAS FRANCO,HANNY MICAL | C37: 7272130 | D37: =+SUM(E37:J37) -> 6 | E37: 1 | F37: 1 | G37: 1 | H37: 1 | I37: 1 | J37: 1 | K37: PF
A38: 36 | B38: ROMERO PRIETO,HEIDY JIANNINA | C38: 7443701 | D38: =+SUM(E38:J38) -> 6 | E38: 1 | F38: 1 | G38: 1 | H38: 1 | I38: 1 | J38: 1 | K38: P
A39: 37 | B39: SALCEDO AYALA,CHRISTOPHER RODRIGO | C39: 7542562 | D39: =+SUM(E39:J39) -> 6 | E39: 1 | F39: 1 | G39: 1 | H39: 1 | I39: 1 | J39: 1 | K39: P
A40: 38 | B40: SAMANIEGO ROJAS,ALEX DAVID | C40: 8000217 | D40: =+SUM(E40:J40) -> 6 | E40: 1 | F40: 1 | G40: 1 | H40: 1 | I40: 1 | J40: 1 | K40: P
...

Sheet Habitos Saludables
D2: Total | E2: Responsabilidad: Tomar decisiones saludables para el bienestar propio y el de los demás, por ejemplo, eligiendo alimentos nutritivos o participando en actividades físicas. | F2: Respeto: Mostrar consideración hacia los demás y sus decisiones, por ejemplo, respetar el derecho de cada persona a cuidar su salud de la manera que elija. | G2: Solidaridad: Promover un entorno en el que todos se ayuden mutuamente a adoptar hábitos saludables, como apoyar a un compañero que decide mejorar su alimentación o hacer ejercicio. | H2: Reflexión ética: Pensar y cuestionar cómo nuestras decisiones afectan a nuestra salud y a la de los demás, tomando en cuenta el bienestar colectivo | I2: Impacto en la toma de decisiones grupales: Observar cómo las decisiones éticas y responsables se aplican en las actividades en grupo y cómo esto afecta la dinámica colectiva. | J2: =+Asistencia!P2 -> Prog. Emb. Habitos
A3: 1 | B3: ARCE CABALLERO,NAHIARA NOEMI | C3: 7344430 | D3: =+SUM(E3:I3) -> 5 | E3: 1 | F3: 1 | G3: 1 | H3: 1 | I3: 1 | J3: P
A4: 2 | B4: ARCE CONTESSI,GUADALUPE MARIA LUJAN | C4: 7503128 | D4: =+SUM(E4:I4) -> 4 | E4: 1 | G4: 1 | H4: 1 | I4: 1 | J4: A
A5: 3 | B5: AYALA MAIDANA,ALMA ISABELLA | C5: 7343210 | D5: =+SUM(E5:I5) -> 5 | E5: 1 | F5: 1 | G5: 1 | H5: 1 | I5: 1 | J5: pf
A6: 4 | B6: BARRETO AYALA,GUADALUPE MABEL | C6: 7474276 | D6: =+SUM(E6:I6) -> 5 | E6: 1 | F6: 1 | G6: 1 | H6: 1 | I6: 1 | J6: pf
A7: 5 | B7: BARRIOS MONGES,LUIS JESUS | C7: 7958599 | D7: =+SUM(E7:I7) -> 5 | E7: 1 | F7: 1 | G7: 1 | H7: 1 | I7: 1 | J7: pf
A8: 6 | B8: BENITEZ GIMENEZ,LUANA ISABEL | C8: 8101499 | D8: =+SUM(E8:I8) -> 4 | E8: 1 | G8: 1 | H8: 1 | I8: 1 | J8: A
A9: 7 | B9: BOGARIN ZORIA,TAMARY ANGELICA | C9: 7651970 | D9: =+SUM(E9:I9) -> 5 | E9: 1 | F9: 1 | G9: 1 | H9: 1 | I9: 1 | J9: P
A10: 8 | B10: CABALLERO DIAZ,CARLOS RODRIGO | C10: 7222581 | D10: =+SUM(E10:I10) -> 4 | E10: 1 | G10: 1 | H10: 1 | I10: 1 | J10: A
A11: 9 | B11: CACERES ROMAN,THAIS VICTORIA | C11: 7357774 | D11: =+SUM(E11:I11) -> 5 | E11: 1 | F11: 1 | G11: 1 | H11: 1 | I11: 1 | J11: PF
A12: 10 | B12: CONTESSI PEREIRA,PAULA ARIANNA | C12: 7342752 | D12: =+SUM(E12:I12) -> 5 | E12: 1 | F12: 1 | G12: 1 | H12: 1 | I12: 1 | J12: P
A13: 11 | B13: ESTIGARRIBIA ESTIGARRIBIA,BASTTIAN JOSUE | C13: 8375944 | D13: =+SUM(E13:I13) -> 5 | E13: 1 | F13: 1 | G13: 1 | H13: 1 | I13: 1 | J13: P
A14: 12 | B14: FERNANDEZ ARCE,IVONNE VIRGINIA | C14: 7552480 | D14: =+SUM(E14:I14) -> 5 | E14: 1 | F14: 1 | G14: 1 | H14: 1 | I14: 1 | J14: PF
A15: 13 | B15: FERNANDEZ TRINIDAD,EMILIA ARAMI | C15: 7227419 | D15: =+SUM(E15:I15) -> 5 | E15: 1 | F15: 1 | G15: 1 | H15: 1 | I15: 1 | J15: P
A16: 14 | B16: FLORENTIN LEDEZMA,TAMARA NOEMI | C16: 7202209 | D16: =+SUM(E16:I16) -> 4 | E16: 1 | G16: 1 | H16: 1 | I16: 1 | J16: A
A17: 15 | B17: FLORENTIN MARTINEZ,AYLEN PAZCAL | C17: 7265455 | D17: =+SUM(E17:I17) -> 5 | E17: 1 | F17: 1 | G17: 1 | H17: 1 | I17: 1 | J17: PF
A18: 16 | B18: FRANCO ARCE,PAULA YELENNA | C18: 7429371 | D18: =+SUM(E18:I18) -> 5 | E18: 1 | F18: 1 | G18: 1 | H18: 1 | I18: 1 | J18: P
A19: 17 | B19: GAONA BAEZ,JEANELLY GUADALUPE | C19: 7444777 | D19: =+SUM(E19:I19) -> 5 | E19: 1 | F19: 1 | G19: 1 | H19: 1 | I19: 1 | J19: P
A20: 18 | B20: GARCIA VIANCONI,LAUTARO RADAMEL | C20: 7444631 | D20: =+SUM(E20:I20) -> 5 | E20: 1 | F20: 1 | G20: 1 | H20: 1 | I20: 1 | J20: P
A21: 19 | B21: GIMENEZ GALEANO,SANTIAGO MIQUEAS | C21: 7514145 | D21: =+SUM(E21:I21) -> 5 | E21: 1 | F21: 1 | G21: 1 | H21: 1 | I21: 1 | J21: P
A22: 20 | B22: GIRETT PEREIRA,SANTIAGO JAVIER | C22: 7386167 | D22: =+SUM(E22:I22) -> 5 | E22: 1 | F22: 1 | G22: 1 | H22: 1 | I22: 1 | J22: P
A23: 21 | B23: GOMEZ BENITEZ,FREDY ANTONIO | C23: 8036254 | D23: =+SUM(E23:I23) -> 5 | E23: 1 | F23: 1 | G23: 1 | H23: 1 | I23: 1 | J23: P
A24: 22 | B24: GONZALEZ LOPEZ,BETHANIA MONSERRAT | C24: 7805242 | D24: =+SUM(E24:I24) -> 5 | E24: 1 | F24: 1 | G24: 1 | H24: 1 | I24: 1 | J24: P
A25: 23 | B25: IRALA PINIENTA,SHEYLA YAMILET | C25: 7167263 | D25: =+SUM(E25:I25) -> 5 | E25: 1 | F25: 1 | G25: 1 | H25: 1 | I25: 1 | J25: P
A26: 24 | B26: JARA BERNAL,BRAHIAN LIONEL | C26: 7594625 | D26: =+SUM(E26:I26) -> 5 | E26: 1 | F26: 1 | G26: 1 | H26: 1 | I26: 1 | J26: P
A27: 25 | B27: MARTINEZ ROJAS,JOSIAS ARNALDO | C27: 7240549 | D27: =+SUM(E27:I27) -> 5 | E27: 1 | F27: 1 | G27: 1 | H27: 1 | I27: 1 | J27: P
A28: 26 | B28: NOTARIO CABRAL,KARINA LUJAN | C28: 7398696 | D28: =+SUM(E28:I28) -> 5 | E28: 1 | F28: 1 | G28: 1 | H28: 1 | I28: 1 | J28: PF
... A41: 39 | B41: SILVA GARCETE,FREDY MISAEL | C41: 7500428 | D41: =+SUM(E41:I41) -> 5 | E41: 1 | F41: 1 | G41: 1 | H41: 1 | I41: 1 | J41: P
A42: 40 | B42: VERA ALCARAZ, LIZZIE CAROLINA | C42: 7377595 | D42: =+SUM(E42:I42) -> 5 | E42: 1 | F42: 1 | G42: 1 | H42: 1 | I42: 1
B43: DIAZ ACUÑA, MAXIMO RAMÓN | D43: =+SUM(E43:I43) -> 3 | G43: 1 | H43: 1 | I43: 1

Sheet Proceso 
F1: =+SUM(H1:AH1) -> 97 | H1: 7 | J1: 26 | K1: 1 | L1: 24 | M1: 5 | N1: 15 | O1: 6 | P1: 3 | Q1: 10
B2: Nota | C2: Nombre y Apellido / Desarrollo de la Unidad | F2: Puntos | G2: Nota | H2: Firmas | I2: Otras aptitudes | J2: Examen | K2: Uniforme | L2: Feria Pedagogica | M2: Aniversario | N2: Desfile | O2: Indicadores Temas | P2: Indicadores actitudinales | Q2: Mapa mental | R2: Puntos Faltantes
A3: =+G3-B3 -> 1 | B3: 3 | C3: 1 | D3: ARCE CABALLERO,NAHIARA NOEMI | E3: 7344430 | F3: =+SUM(H3:Q3) -> 85 | G3: =LOOKUP(F3,{0,58,68,78,88},{1,2,3,4,5}) -> 4 | H3: =+Asistencia!Z3 -> 7 | I3: 4 | J3: 10 | K3: 1 | L3: 24 | M3: 5 | N3: 15 | O3: =+'La persona'!D3 -> 6 | P3: =+'Indicadores Actitudinal'!D3 -> 3 | Q3: 10 | R3: =26-J3 -> 16
A4: =+G4-B4 -> 0 | B4: 5 | C4: 2 | D4: ARCE CONTESSI,GUADALUPE MARIA LUJAN | E4: 7503128 | F4: =+SUM(H4:Q4) -> 97 | G4: =LOOKUP(F4,{0,58,68,78,88},{1,2,3,4,5}) -> 5 | H4: =+Asistencia!Z4 -> 7 | I4: 4 | J4: 22 | K4: 1 | L4: 24 | M4: 5 | N4: 15 | O4: =+'La persona'!D4 -> 6 | P4: =+'Indicadores Actitudinal'!D4 -> 3 | Q4: 10 | R4: =26-J4 -> 4
A5: =+G5-B5 -> 1 | B5: 4 | C5: 3 | D5: AYALA MAIDANA,ALMA ISABELLA | E5: 7343210 | F5: =+SUM(H5:Q5) -> 91 | G5: =LOOKUP(F5,{0,58,68,78,88},{1,2,3,4,5}) -> 5 | H5: =+Asistencia!Z5 -> 7 | I5: 4 | J5: 16 | K5: 1 | L5: 24 | M5: 5 | N5: 15 | O5: =+'La persona'!D5 -> 6 | P5: =+'Indicadores Actitudinal'!D5 -> 3 | Q5: 10 | R5: =26-J5 -> 10
A6: =+G6-B6 -> 0 | B6: 5 | C6: 4 | D6: BARRETO AYALA,GUADALUPE MABEL | E6: 7474276 | F6: =+SUM(H6:Q6) -> 95 | G6: =LOOKUP(F6,{0,58,68,78,88},{1,2,3,4,5}) -> 5 | H6: =+Asistencia!Z6 -> 7 | I6: 4 | J6: 20 | K6: 1 | L6: 24 | M6: 5 | N6: 15 | O6: =+'La persona'!D6 -> 6 | P6: =+'Indicadores Actitudinal'!D6 -> 3 | Q6: 10 | R6: =26-J6 -> 6
A7: =+G7-B7 -> 0 | B7: 5 | C7: 5 | D7: BARRIOS MONGES,LUIS JESUS | E7: 7958599 | F7: =+SUM(H7:Q7) -> 94 | G7: =LOOKUP(F7,{0,58,68,78,88},{1,2,3,4,5}) -> 5 | H7: =+Asistencia!Z7 -> 7 | I7: 4 | J7: 19 | K7: 1 | L7: 24 | M7: 5 | N7: 15 | O7: =+'La persona'!D7 -> 6 | P7: =+'Indicadores Actitudinal'!D7 -> 3 | Q7: 10 | R7: =26-J7 -> 7
A8: =+G8-B8 -> 0 | B8: 5 | C8: 6 | D8: BENITEZ GIMENEZ,LUANA ISABEL | E8: 8101499 | F8: =+SUM(H8:Q8) -> 94 | G8: =LOOKUP(F8,{0,58,68,78,88},{1,2,3,4,5}) -> 5 | H8: =+Asistencia!Z8 -> 7 | I8: 4 | J8: 19 | K8: 1 | L8: 24 | M8: 5 | N8: 15 | O8: =+'La persona'!D8 -> 6 | P8: =+'Indicadores Actitudinal'!D8 -> 3 | Q8: 10 | R8: =26-J8 -> 7
A9: =+G9-B9 -> 1 | B9: 4 | C9: 7 | D9: BOGARIN ZORIA,TAMARY ANGELICA | E9: 7651970 | F9: =+SUM(H9:Q9) -> 90 | G9: =LOOKUP(F9,{0,58,68,78,88},{1,2,3,4,5}) -> 5 | H9: =+Asistencia!Z9 -> 6 | I9: 4 | J9: 16 | K9: 1 | L9: 24 | M9: 5 | N9: 15 | O9: =+'La persona'!D9 -> 6 | P9: =+'Indicadores Actitudinal'!D9 -> 3 | Q9: 10 | R9: =26-J9 -> 10
A10: =+G10-B10 -> 0 | B10: 5 | C10: 8 | D10: CABALLERO DIAZ,CARLOS RODRIGO | E10: 7222581 | F10: =+SUM(H10:Q10) -> 94 | G10: =LOOKUP(F10,{0,58,68,78,88},{1,2,3,4,5}) -> 5 | H10: =+Asistencia!Z10 -> 7 | I10: 4 | J10: 19 | K10: 1 | L10: 24 | M10: 5 | N10: 15 | O10: =+'La persona'!D10 -> 6 | P10: =+'Indicadores Actitudinal'!D10 -> 3 | Q10: 10 | R10: =26-J10 -> 7
A11: =+G11-B11 -> 0 | B11: 5 | C11: 9 | D11: CACERES ROMAN,THAIS VICTORIA | E11: 7357774 | F11: =+SUM(H11:Q11) -> 96 | G11: =LOOKUP(F11,{0,58,68,78,88},{1,2,3,4,5}) -> 5 | H11: =+Asistencia!Z11 -> 7 | I11: 4 | J11: 21 | K11: 1 | L11: 24 | M11: 5 | N11: 15 | O11: =+'La persona'!D11 -> 6 | P11: =+'Indicadores Actitudinal'!D11 -> 3 | Q11: 10 | R11: =26-J11 -> 5
A12: =+G12-B12 -> 0 | B12: 5 | C12: 10 | D12: CONTESSI PEREIRA,PAULA ARIANNA | E12: 7342752 | F12: =+SUM(H12:Q12) -> 97 | G12: =LOOKUP(F12,{0,58,68,78,88},{1,2,3,4,5}) -> 5 | H12: =+Asistencia!Z12 -> 6 | I12: 4 | J12: 23 | K12: 1 | L12: 24 | M12: 5 | N12: 15 | O12: =+'La persona'!D12 -> 6 | P12: =+'Indicadores Actitudinal'!D12 -> 3 | Q12: 10 | R12: =26-J12 -> 3
A13: =+G13-B13 -> 1 | B13: 3 | C13: 11 | D13: ESTIGARRIBIA ESTIGARRIBIA,BASTTIAN JOSUE | E13: 8375944 | F13: =+SUM(H13:Q13) -> 84 | G13: =LOOKUP(F13,{0,58,68,78,88},{1,2,3,4,5}) -> 4 | H13: =+Asistencia!Z13 -> 7 | I13: 4 | J13: 9 | K13: 1 | L13: 24 | M13: 5 | N13: 15 | O13: =+'La persona'!D13 -> 6 | P13: =+'Indicadores Actitudinal'!D13 -> 3 | Q13: 10 | R13: =26-J13 -> 17
A14: =+G14-B14 -> 0 | B14: 5 | C14: 12 | D14: FERNANDEZ ARCE,IVONNE VIRGINIA | E14: 7552480 | F14: =+SUM(H14:Q14) -> 97 | G14: =LOOKUP(F14,{0,58,68,78,88},{1,2,3,4,5}) -> 5 | H14: =+Asistencia!Z14 -> 7 | I14: 4 | J14: 22 | K14: 1 | L14: 24 | M14: 5 | N14: 15 | O14: =+'La persona'!D14 -> 6 | P14: =+'Indicadores Actitudinal'!D14 -> 3 | Q14: 10 | R14: =26-J14 -> 4
... A42: =+G42-B42 -> 0 | B42: 4 | C42: 40 | D42: VERA ALCARAZ, LIZZIE CAROLINA | E42: 7377595 | F42: =+SUM(H42:Q42) -> 87 | G42: =LOOKUP(F42,{0,58,68,78,88},{1,2,3,4,5}) -> 4 | H42: =+Asistencia!Z42 -> 5 | I42: 4 | J42: 14 | K42: 1 | L42: 24 | M42: 5 | N42: 15 | O42: =+'La persona'!D42 -> 6 | P42: =+'Indicadores Actitudinal'!D42 -> 3 | Q42: 10 | R42: =26-J42 -> 12
A43: =+G43-B43 -> 0 | B43: 4 | C43: 41 | D43: DIAZ ACUÑA, MAXIMO RAMÓN | F43: =+SUM(H43:Q43) -> 83 | G43: =LOOKUP(F43,{0,58,68,78,88},{1,2,3,4,5}) -> 4 | H43: =+Asistencia!Z43 -> 0 | I43: 4 | J43: 17 | K43: 1 | L43: 24 | M43: 5 | N43: 15 | O43: =+'La persona'!D43 -> 5 | P43: =+'Indicadores Actitudinal'!D43 -> 2 | Q43: 10 | R43: =26-J43 -> 9
L44: =+SUM(L3:L43)/24 -> 41 | M44: =+SUM(M3:M43)/5 -> 41 | N44: =+SUM(N3:N43)/15 -> 41 | O44: =+SUM(O3:O43)/6 -> 40.166667 | P44: =+SUM(P3:P43)/3 -> 38.333333 | Q44: =+SUM(Q3:Q43)/10 -> 41

Sheet Escala
A1: COLEGIO SAGRADA FAMILIA
A2: ESCALA DE CALIFICACIONES - 60%
A4: 15 Puntos | B4: 16 Puntos | C4: 17 Puntos | D4: 18 Puntos | E4: 19 Puntos | F4: 20 Puntos | G4: 21 Puntos | H4: 22 Puntos
A5: 0 - 9 = 1 | B5: 0 - 9 = 1 | C5: 0 - 10 = 1 | D5: 0 - 10 = 1 | E5: 0 - 10 = 1 | F5: 0 - 11 = 1 | G5: 0 - 12 = 1 | H5: 0 - 13 = 1
A6: 9 - 10 = 2 | B6: 9 - 10 = 2 | C6: 11 - 12 = 2 | D6: 11 - 12 = 2 | E6: 11 - 12 = 2 | F6: 12 - 13 = 2 | G6: 13 - 14 = 2 | H6: 14 - 15 = 2
A7: 11 - 12 = 3 | B7: 11 - 12 = 3 | C7: 13 - 14 = 3 | D7: 13 - 14 = 3 | E7: 13 - 15 = 3 | F7: 14 - 16 = 3 | G7: 15 - 17 = 3 | H7: 16 - 18 = 3
A8: 13 - 14 = 4 | B8: 13 - 14 = 4 | C8: 15 - 16 = 4 | D8: 15 - 16 = 4 | E8: 16 - 17 = 4 | F8: 17 - 18 = 4 | G8: 18 - 19 = 4 | H8: 19 - 20 = 4
A9: 15 = 5 | B9: 15 - 16 = 5 | C9: 17 = 5 | D9: 17 - 18 = 5 | E9: 18 - 19 = 5 | F9: 19 - 20 = 5 | G9: 20 - 21 = 5 | H9: 21 - 22 = 5
A11: 23 Puntos | B11: 24 Puntos | C11: 25 Puntos | D11: 26 Puntos | E11: 27 Puntos | F11: 28 Puntos | G11: 29 Puntos | H11: 30 Puntos
A12: 0 - 13 = 1 | B12: 0 - 13 = 1 | C12: 0 - 14 = 1 | D12: 0 - 15 = 1 | E12: 0 - 15 = 1 | F12: 0 - 16 = 1 | G12: 0 - 17 = 1 | H12: 0 - 17 = 1
A13: 14 - 15 = 2 | B13: 14 - 16 = 2 | C13: 15 - 17 = 2 | D13: 16 - 18 = 2 | E13: 16 - 18 = 2 | F13: 17 - 19 = 2 | G13: 18 - 20 = 2 | H13: 18 - 20 = 2
A14: 16 - 18 = 3 | B14: 17 - 19 = 3 | C14: 18 - 20 = 3 | D14: 19 - 21 = 3 | E14: 19 - 21 = 3 | F14: 20 - 22 = 3 | G14: 21 - 23 = 3 | H14: 21 - 24 = 3
A15: 19 - 21 = 4 | B15: 20 - 22 = 4 | C15: 21 - 23 = 4 | D15: 22 - 24 = 4 | E15: 22 - 24 = 4 | F15: 23 - 25 = 4 | G15: 24 - 26 = 4 | H15: 25 - 27 = 4
A16: 22 - 23 = 5 | B16: 23 - 24 = 5 | C16: 24 - 25 = 5 | D16: 25 - 26 = 5 | E16: 25 - 27 = 5 | F16: 26 - 28 = 5 | G16: 27 - 29 = 5 | H16: 28 - 30 = 5
... A51: 58 - 63 = 5 | B51: 59 - 64 = 5 | C51: 60 - 65 = 5 | D51: 61 - 66 = 5 | E51: 61 - 67 = 5 | F51: 62 - 68 = 5 | G51: 63 - 69 = 5 | H51: 64 - 70 = 5
A56: COLEGIO SAGRADA FAMILIA
A57: ESCALA DE CALIFICACIONES - 60%
A59: 71 Puntos | B59: 72 Puntos | C59: 73 Puntos | D59: 74 Puntos | E59: 75 Puntos | F59: 76 Puntos | G59: 77 Puntos | H59: 78 Puntos
A60: 0 - 42 = 1 | B60: 0 - 42 = 1 | C60: 0 - 43 = 1 | D60: 0 - 43 = 1 | E60: 0 - 44 = 1 | F60: 0 - 45 = 1 | G60: 0 - 45 = 1 | H60: 0 - 46 = 1
A61: 43 - 49 = 2 | B61: 43 - 49 = 2 | C61: 44 - 50 = 2 | D61: 44 - 51 = 2 | E61: 45 - 52 = 2 | F61: 46 - 53 = 2 | G61: 46 - 53 = 2 | H61: 47 - 54 = 2
A62: 50 - 57 = 3 | B62: 50 - 57 = 3 | C62: 51 - 58 = 3 | D62: 52 - 59 = 3 | E62: 53 - 60 = 3 | F62: 54 - 61 = 3 | G62: 54 - 61 = 3 | H62: 55 - 62 = 3
A63: 58 - 64 = 4 | B63: 58 - 65 = 4 | C63: 59 - 66 = 4 | D63: 60 - 67 = 4 | E63: 61 - 68 = 4 | F63: 62 - 69 = 4 | G63: 62 - 69 = 4 | H63: 63 - 70 = 4
A64: 65 - 71 = 5 | B64: 66 - 72 = 5 | C64: 67 - 73 = 5 | D64: 68 - 74 = 5 | E64: 69 - 75 = 5 | F64: 70 - 76 = 5 | G64: 70 - 77 = 5 | H64: 71 - 78 = 5
A66: 79 Puntos | B66: 80 Puntos | C66: 81 Puntos | D66: 82 Puntos | E66: 83 Puntos | F66: 84 Puntos | G66: 85 Puntos | H66: 86 Puntos
A67: 0 - 46 = 1 | B67: 0 - 47 = 1 | C67: 0 - 48 = 1 | D67: 0 - 48 = 1 | E67: 0 - 48 = 1 | F67: 0 - 49 = 1 | G67: 0 - 50 = 1 | H67: 0 - 51 = 1
A68: 47 - 54 = 2 | B68: 48 - 55 = 2 | C68: 49 - 56 = 2 | D68: 49 - 56 = 2 | E68: 49 - 57 = 2 | F68: 50 - 58 = 2 | G68: 51 - 59 = 2 | H68: 52 - 60 = 2
A69: 55 - 63 = 3 | B69: 56 - 64 = 3 | C69: 57 - 65 = 3 | D69: 57 - 65 = 3 | E69: 58 - 66 = 3 | F69: 59 - 67 = 3 | G69: 60 - 68 = 3 | H69: 61 - 69 = 3
A70: 64 - 71 = 4 | B70: 65 - 72 = 4 | C70: 66 - 73 = 4 | D70: 66 - 74 = 4 | E70: 67 - 75 = 4 | F70: 68 - 76 = 4 | G70: 69 - 77 = 4 | H70: 70 - 78 = 4
A71: 72 - 79 = 5 | B71: 73 - 80 = 5 | C71: 74 - 81 = 5 | D71: 75 - 82 = 5 | E71: 76 - 83 = 5 | F71: 77 - 84 = 5 | G71: 78 - 85 = 5 | H71: 79 - 86 = 5
... A106: 108-119= 5 | B106: 109-120= 5 | C106: 110-121= 5 | D106: 111-122= 5 | E106: 112-123= 5 | F106: 113-124= 5 | G106: 114-125= 5 | H106: 115-126= 5
