Workbook

Sheet V1_Prinicipal
A1: INSTITUCION | G1: Promedio de Asistencia
A2: ESC.EXC. Manuel | D2: Dias de clase | E2: Viernes | G2: =+'03-ASISTENCIA'!D2
A3: Molinas | D3: Horas ingreso | E3: 0.54166667
D4: Hora salida | E4: 0.63194444
A5: GRADO | D5: Receso | E5: 0.010416667
A6: SEPTIMO | D6: Horas cátedras | E6: =+(E4-E3)*3600/(40*60)-E5
A8: TURNO | D8: INTRUMENTOS | J8: Plan Unidad 1
A9: TARDE | C9: 1 | D9: PLAN ANUAL | J9: Plan Unidad 2
C10: 2 | D10: REGISTRO DE TEMAS | J10: Plan Unidad 3
A11: ASIGNATURA | C11: 3 | D11: ASISTENCIA | J11: Plan Unidad 4
A12: FORMACIÓN ETICA | C12: 4 | D12: RSA | J12: Plan Unidad 5
C13: 5 | D13: CUADRO ANECDOTICO | J13: Plan Unidad 6
A14: PROFESOR | D14: INSTITUCIONAL | J14: Plan Unidad 7
A15: CHRISTHIAN KEIM | C15: 6 | D15: POA 2026 | J15: Plan Unidad 8
C16: 7 | D16: POA 2026 - ASIGNATURA | J16: Plan Unidad 9
A17: 2026 | C17: 8 | D17: CALENDARIO MEC | J17: Plan Unidad 10
C18: 9 | D18: PROYECTOS INSTITUCIONALES
C19: 10 | D19: INDICADORES ACTITUDINALES
C20: 11 | D20: DIAGNOSTICO

Sheet V1_01-PLAN_ANUAL
A1: Unidad Temática | B1: Capacidades | C1: Contenido | D1: Estrategias Didácticas | E1: Indicadores | F1: Estrategias evaluativas | G1: Recursos Didácticos
A2: Persona y entorno | B2: Reflexiona acerca de la práctica de los principios y valores democráticos. | C2: Ética y Moral. Diferencias y moralidad social. | D2: - Responde preguntas. | E2: - Identifica principios éticos y morales. | F2: - Portafolio de trabajo. | G2: - Cuadernillo Serie Poty.
A3: Persona y entorno | B3: Reflexiona acerca de la práctica de los principios y valores democráticos. | C3: Ética y Moral. Diferencias y moralidad social. | D3: - Establece diferencias entre ética y moral. | E3: - Diferencia moral y moralidad. | F3: - RSA con indicadores. | G3: - Cartulinas y pinceles.
A4: Persona y entorno | B4: Reflexiona acerca de la práctica de los principios y valores democráticos. | C4: Ética y Moral. Diferencias y moralidad social. | D4: - Diseña carteles de concientización.
A5: Persona y entorno | B5: Analiza dilemas éticos contemporáneos y su impacto social. | C5: **Escándalos éticos de nuestro tiempo:** Pobreza, hambre y mortalidad infantil. | D5: - Análisis de noticias actuales. | E5: - Reconoce problemáticas éticas globales. | F5: - Registro de observación. | G5: - Material de lectura.
A6: Persona y entorno | B6: Analiza dilemas éticos contemporáneos y su impacto social. | C6: **Escándalos éticos de nuestro tiempo:** Pobreza, hambre y mortalidad infantil. | D6: - Debate sobre déficit de agua potable. | E6: - Analiza causas de la mortalidad infantil. | F6: - Ensayos escritos. | G6: - Artículos de prensa.
A7: Persona y entorno | B7: Analiza dilemas éticos contemporáneos y su impacto social. | C7: **Escándalos éticos de nuestro tiempo:** Pobreza, hambre y mortalidad infantil. | D7: - Elaboración de ensayos breves.
A8: Persona y entorno | B8: Comprende la importancia de la convivencia armónica en el ámbito escolar. | C8: **Acuerdos de relacionamiento:** Código de convivencia docente-estudiante. | D8: - Lluvia de ideas sobre normas. | E8: - Valora el código de convivencia. | F8: - Participación activa. | G8: - Papelógrafos.
A9: Persona y entorno | B9: Comprende la importancia de la convivencia armónica en el ámbito escolar. | C9: **Acuerdos de relacionamiento:** Código de convivencia docente-estudiante. | D9: - Redacción participativa de acuerdos de aula. | E9: - Propone normas de respeto mutuo. | F9: - Documento de acuerdos. | G9: - Marcadores.
A10: Persona y entorno | B10: Identifica situaciones de acoso escolar y propone medidas de prevención. | C10: Bullying: Concepto, tipos, causas y consecuencias. | D10: (Abordaje > 2 horas) | E10: - Define tipos de bullying. | F10: - Guía de trabajo grupal. | G10: - Proyector / Videos.
A11: Persona y entorno | B11: Identifica situaciones de acoso escolar y propone medidas de prevención. | C11: Bullying: Concepto, tipos, causas y consecuencias. | D11: - Cine debate sobre casos reales. | E11: - Identifica consecuencias psicológicas.
A12: Persona y entorno | B12: Identifica situaciones de acoso escolar y propone medidas de prevención. | C12: Bullying: Concepto, tipos, causas y consecuencias. | D12: - Talleres de rol (agresor/víctima). | E12: - Propone acciones de prevención. | F12: - RSA. | G12: - Fichas de casos.
A13: Persona y entorno | B13: Identifica situaciones de acoso escolar y propone medidas de prevención. | C13: Bullying: Concepto, tipos, causas y consecuencias. | D13: - Elaboración de protocolos de ayuda.
A14: Persona y entorno | B14: Aplica técnicas básicas de resolución de conflictos en situaciones cotidianas. | C14: Mediación, Negociación y Confrontación. | D14: (Abordaje > 2 horas) | E14: - Diferencia mediación de negociación. | F14: - Evaluación de desempeño (Role-play). | G14: - Guiones de casos.
A15: Persona y entorno | B15: Aplica técnicas básicas de resolución de conflictos en situaciones cotidianas. | C15: Mediación, Negociación y Confrontación. | D15: - Simulacros de mediación escolar.
A16: Persona y entorno | B16: Aplica técnicas básicas de resolución de conflictos en situaciones cotidianas. | C16: Mediación, Negociación y Confrontación. | D16: - Ejercicios de comunicación asertiva. | E16: - Aplica pasos de la negociación asertiva. | G16: - Pizarra.
A17: Persona y entorno | B17: Aplica técnicas básicas de resolución de conflictos en situaciones cotidianas. | C17: Mediación, Negociación y Confrontación. | D17: - Análisis de casos de conflicto.
A18: La Familia | B18: Analiza la situación socioeconómica de las familias paraguayas. | C18: Pobreza y Canasta Básica Familiar. | D18: - Investigación de precios actuales. | E18: - Define el concepto de canasta básica. | F18: - Informe de investigación. | G18: - Datos estadísticos.
A19: La Familia | B19: Analiza la situación socioeconómica de las familias paraguayas. | C19: Pobreza y Canasta Básica Familiar. | D19: - Comparación de ingresos y costos básicos. | E19: - Analiza el impacto de la pobreza. | F19: - Cuadro comparativo. | G19: - Calculadora.
A20: La Familia | B20: Reconoce factores que inciden en la violencia intrafamiliar. | C20: Violencia Intrafamiliar: Causas y prevención. | D20: (Abordaje > 2 horas) | E20: - Identifica tipos de violencia familiar. | F20: - Cuestionario reflexivo. | G20: - Trípticos informativos.
A21: La Familia | B21: Reconoce factores que inciden en la violencia intrafamiliar. | C21: Violencia Intrafamiliar: Causas y prevención. | D21: - Charla con especialistas o videos informativos. | E21: - Conoce rutas de denuncia en Paraguay. | F21: - RSA. | G21: - Proyector.
A22: La Familia | B22: Reconoce factores que inciden en la violencia intrafamiliar. | C22: Violencia Intrafamiliar: Causas y prevención. | D22: - Análisis de la Ley contra violencia doméstica.
A23: La Familia | B23: Reconoce factores que inciden en la violencia intrafamiliar. | C23: Violencia Intrafamiliar: Causas y prevención. | D23: - Mapa de instituciones de denuncia.
A24: Derechos Humanos | B24: Reconoce los principios básicos que rigen los Derechos Humanos. | C24: Principios de los DD.HH.: Universalidad, progresividad e irreversibilidad. | D24: (Abordaje > 2 horas) | E24: - Explica la universalidad de los derechos. | F24: - Mapa conceptual. | G24: - Constitución Nacional.
A25: Derechos Humanos | B25: Reconoce los principios básicos que rigen los Derechos Humanos. | C25: Principios de los DD.HH.: Universalidad, progresividad e irreversibilidad. | D25: - Lectura comprensiva de la Declaración Universal.
A26: Derechos Humanos | B26: Reconoce los principios básicos que rigen los Derechos Humanos. | C26: Principios de los DD.HH.: Universalidad, progresividad e irreversibilidad. | D26: - Análisis de casos históricos. | E26: - Distingue progresividad de irreversibilidad. | F26: - Prueba escrita formativa. | G26: - Textos guía.
A27: Derechos Humanos | B27: Reconoce los principios básicos que rigen los Derechos Humanos. | C27: Principios de los DD.HH.: Universalidad, progresividad e irreversibilidad. | D27: - Debate sobre la temporalidad de los derechos.
A28: Derechos Humanos | B28: Analiza situaciones de vulneración de derechos en la niñez y adolescencia. | C28: **Causas de explotación:** Sexual, laboral y trabajos forzados. | D28: - Análisis de estadísticas nacionales. | E28: - Reconoce formas de explotación infantil. | F28: - Murales preventivos. | G28: - Afiches.
A29: Derechos Humanos | B29: Analiza situaciones de vulneración de derechos en la niñez y adolescencia. | C29: **Causas de explotación:** Sexual, laboral y trabajos forzados. | D29: - Identificación de señales de riesgo. | E29: - Valora la protección contra el trabajo forzado. | F29: - Portafolio. | G29: - Material audiovisual.
A30: Derechos Humanos | B30: Analiza situaciones de vulneración de derechos en la niñez y adolescencia. | C30: **Causas de explotación:** Sexual, laboral y trabajos forzados. | D30: - Elaboración de campañas preventivas.
A31: Democracia y Estado | B31: Analiza la situación de la mujer en la estructura social actual. | C31: **Pobreza, desigualdad y exclusión a la mujer.** | D31: - Debate sobre brecha salarial y acceso a educación. | E31: - Identifica factores de exclusión femenina. | F31: - RSA. | G31: - Material de lectura.
A32: Democracia y Estado | B32: Analiza la situación de la mujer en la estructura social actual. | C32: **Pobreza, desigualdad y exclusión a la mujer.** | D32: - Biografías de mujeres líderes en Paraguay. | E32: - Propone acciones para la igualdad. | F32: - Debate dirigido. | G32: - Artículos de género.
A33: Democracia y Estado | B33: Analiza el Sistema Tributario en función al fortalecimiento institucional. | C33: Sistema Tributario y funciones de la S.E.T. | D33: (Abordaje > 2 horas) | E33: - Identifica la función tributaria. | F33: - Ejercicios prácticos. | G33: - Formularios de práctica.
A34: Democracia y Estado | B34: Analiza el Sistema Tributario en función al fortalecimiento institucional. | C34: Sistema Tributario y funciones de la S.E.T. | D34: - Taller sobre el IVA y su importancia social.
A35: Democracia y Estado | B35: Analiza el Sistema Tributario en función al fortalecimiento institucional. | C35: Sistema Tributario y funciones de la S.E.T. | D35: - Visita virtual o análisis de la página de la SET. | E35: - Valora la función social de los tributos. | F35: - Portafolio. | G35: - Internet.
A36: Democracia y Estado | B36: Analiza el Sistema Tributario en función al fortalecimiento institucional. | C36: Sistema Tributario y funciones de la S.E.T. | D36: - Ejercicios de cálculo básico de impuestos.
A37: Democracia y Estado | B37: Analiza la estructura y funciones de los organismos del Estado. | C37: Ministerio de Hacienda y Autoridades Locales (Intendencias/Gobernaciones). | D37: - Elaboración de organigrama del Estado. | E37: - Reconoce funciones del Ministerio de Hacienda. | F37: - Mapa conceptual. | G37: - Organigrama estatal.
A38: Democracia y Estado | B38: Analiza la estructura y funciones de los organismos del Estado. | C38: Ministerio de Hacienda y Autoridades Locales (Intendencias/Gobernaciones). | D38: - Investigación sobre funciones municipales. | E38: - Diferencia roles de Intendentes y Gobernadores. | F38: - RSA. | G38: - Páginas web oficiales.
A39: Democracia y Estado | B39: Analiza la estructura y funciones de los organismos del Estado. | C39: Ministerio de Hacienda y Autoridades Locales (Intendencias/Gobernaciones). | D39: - Entrevista a autoridades o análisis de gestión.

Sheet V1_02-REGISTRO_DE_TEMAS
B1: PLANILLA DE EJECUCIÓN DE CLASES | E1: 2026
C2: Plan de Clases | D2: ESTADO | E2: Ejecutado
A3: =+B3 | B3: 46079 | D3: =IFERROR(VLOOKUP(B3, fechaMEC, 3, FALSE), "Clase Normal") | E3: =IFERROR(VLOOKUP(B3, fechaMEC, 2, FALSE), "Ejecutado")
A4: =+B4 | B4: 46086 | C4: Dinamica -concepto de etica y moral | D4: =IFERROR(VLOOKUP(B4, fechaMEC, 3, FALSE), "Clase Normal") | E4: =IFERROR(VLOOKUP(B4, fechaMEC, 2, FALSE), "Ejecutado")
A5: =+B5 | B5: 46093 | C5: concepto de etica y moral | D5: =IFERROR(VLOOKUP(B5, fechaMEC, 3, FALSE), "Clase Normal") | E5: =IFERROR(VLOOKUP(B5, fechaMEC, 2, FALSE), "Ejecutado")
A6: =+B6 | B6: 46100 | C6: concepto de etica y moral | D6: =IFERROR(VLOOKUP(B6, fechaMEC, 3, FALSE), "Clase Normal") | E6: =IFERROR(VLOOKUP(B6, fechaMEC, 2, FALSE), "Ejecutado")
A7: =+B7 | B7: 46107 | C7: Moralidad y normas morales | D7: =IFERROR(VLOOKUP(B7, fechaMEC, 3, FALSE), "Clase Normal") | E7: =IFERROR(VLOOKUP(B7, fechaMEC, 2, FALSE), "Ejecutado")
A8: =+B8 | B8: 46114 | D8: =IFERROR(VLOOKUP(B8, fechaMEC, 3, FALSE), "Clase Normal") | E8: =IFERROR(VLOOKUP(B8, fechaMEC, 2, FALSE), "Ejecutado")
A9: =+B9 | B9: 46121 | C9: Moralidad y normas morales | D9: =IFERROR(VLOOKUP(B9, fechaMEC, 3, FALSE), "Clase Normal") | E9: =IFERROR(VLOOKUP(B9, fechaMEC, 2, FALSE), "Ejecutado")
A10: =+B10 | B10: 46128 | D10: =IFERROR(VLOOKUP(B10, fechaMEC, 3, FALSE), "Clase Normal") | E10: =IFERROR(VLOOKUP(B10, fechaMEC, 2, FALSE), "Ejecutado")
A11: =+B11 | B11: 46135 | D11: =IFERROR(VLOOKUP(B11, fechaMEC, 3, FALSE), "Clase Normal")
A12: =+B12 | B12: 46142 | D12: =IFERROR(VLOOKUP(B12, fechaMEC, 3, FALSE), "Clase Normal") | E12: =IFERROR(VLOOKUP(B12, fechaMEC, 2, FALSE), "Ejecutado")
A13: =+B13 | B13: 46149 | D13: =IFERROR(VLOOKUP(B13, fechaMEC, 3, FALSE), "Clase Normal")
A14: =+B14 | B14: 46156 | D14: =IFERROR(VLOOKUP(B14, fechaMEC, 3, FALSE), "Clase Normal") | E14: =IFERROR(VLOOKUP(B14, fechaMEC, 2, FALSE), "Ejecutado")
A15: =+B15 | B15: 46163 | D15: =IFERROR(VLOOKUP(B15, fechaMEC, 3, FALSE), "Clase Normal")
A16: =+B16 | B16: 46170 | C16: Evaluacion | D16: =IFERROR(VLOOKUP(B16, fechaMEC, 3, FALSE), "Clase Normal") | E16: Evaluación
A17: =+B17 | B17: 46177 | D17: =IFERROR(VLOOKUP(B17, fechaMEC, 3, FALSE), "Clase Normal")
A18: =+B18 | B18: 46184 | D18: =IFERROR(VLOOKUP(B18, fechaMEC, 3, FALSE), "Clase Normal") | E18: =IFERROR(VLOOKUP(B18, fechaMEC, 2, FALSE), "Ejecutado") | H18: Fecha (DD/MM/YYYY) | I18: Evento / Conmemoración | J18: Tipo
A19: =+B19 | B19: 46191 | D19: =IFERROR(VLOOKUP(B19, fechaMEC, 3, FALSE), "Clase Normal") | E19: =IFERROR(VLOOKUP(B19, fechaMEC, 2, FALSE), "Ejecutado") | H19: 46023 | I19: Año Nuevo | J19: Feriado Nacional
A20: =+B20 | B20: 46198 | D20: =IFERROR(VLOOKUP(B20, fechaMEC, 3, FALSE), "Clase Normal") | H20: 46063 | I20: Apertura Institucional y Retorno Docente | J20: MEC - INSTITUCIONAL
A21: =+B21 | B21: 46205 | C21: Examen Primera Etapa | D21: =IFERROR(VLOOKUP(B21, fechaMEC, 3, FALSE), "Clase Normal") | H21: 46076 | I21: Inicio de Clases (Sector Oficial) | J21: MEC - INSTITUCIONAL
A22: =+B22 | B22: 46212 | D22: =IFERROR(VLOOKUP(B22, fechaMEC, 3, FALSE), "Clase Normal") | H22: 46077 | I22: Día de la Mujer Paraguaya (Homenaje a las Residentas) | J22: Dia para conmemorar
A23: =+B23 | B23: 46219 | C23: Vacaciones de Invierno | D23: =IFERROR(VLOOKUP(B23, fechaMEC, 3, FALSE), "Clase Normal") | E23: =IFERROR(VLOOKUP(B23, fechaMEC, 2, FALSE), "Ejecutado") | H23: 46082 | I23: Día de los Héroes | J23: Feriado Nacional
A24: =+B24 | B24: 46226 | C24: Vacaciones de Invierno | D24: =IFERROR(VLOOKUP(B24, fechaMEC, 3, FALSE), "Clase Normal") | E24: =IFERROR(VLOOKUP(B24, fechaMEC, 2, FALSE), "Ejecutado") | H24: 46082 | I24: Día de los Héroes (Muerte del Mcal. López en Cerro Corá) | J24: Dia para conmemorar
A25: =+B25 | B25: 46233 | D25: =IFERROR(VLOOKUP(B25, fechaMEC, 3, FALSE), "Clase Normal") | H25: 46102 | I25: Día Mundial de la Poesía y Día del Síndrome de Down | J25: Dia para conmemorar
A26: =+B26 | B26: 46240 | D26: =IFERROR(VLOOKUP(B26, fechaMEC, 3, FALSE), "Clase Normal") | H26: 46114 | I26: Jueves Santo (Receso) | J26: Feriado Nacional
A27: =+B27 | B27: 46247 | D27: =IFERROR(VLOOKUP(B27, fechaMEC, 3, FALSE), "Clase Normal") | E27: =IFERROR(VLOOKUP(B27, fechaMEC, 2, FALSE), "Ejecutado") | H27: 46115 | I27: Viernes Santo (Receso) | J27: Feriado Nacional
A28: =+B28 | B28: 46254 | D28: =IFERROR(VLOOKUP(B28, fechaMEC, 3, FALSE), "Clase Normal") | H28: 46135 | I28: Día del Libro y del Derecho de Autor | J28: Dia para conmemorar
A29: =+B29 | B29: 46261 | D29: =IFERROR(VLOOKUP(B29, fechaMEC, 3, FALSE), "Clase Normal") | H29: 46138 | I29: Día del Periodista (Muerte de Santiago Leguizamón) | J29: Dia para conmemorar
A30: =+B30 | B30: 46268 | D30: =IFERROR(VLOOKUP(B30, fechaMEC, 3, FALSE), "Clase Normal") | H30: 46142 | I30: Día del Maestro (En Paraguay) | J30: Dia para conmemorar
A31: =+B31 | B31: 46275 | D31: =IFERROR(VLOOKUP(B31, fechaMEC, 3, FALSE), "Clase Normal") | H31: 46143 | I31: Día de los Trabajadores | J31: Feriado Nacional
A32: =+B32 | B32: 46282 | D32: =IFERROR(VLOOKUP(B32, fechaMEC, 3, FALSE), "Clase Normal") | H32: 46156 | I32: Día de la Independencia Nacional | J32: Feriado Nacional
A33: =+B33 | B33: 46289 | D33: =IFERROR(VLOOKUP(B33, fechaMEC, 3, FALSE), "Clase Normal") | H33: 46156 | I33: Día de la Madre | J33: Dia para conmemorar
A34: =+B34 | B34: 46296 | D34: =IFERROR(VLOOKUP(B34, fechaMEC, 3, FALSE), "Clase Normal") | H34: 46157 | I34: Día de la Independencia Nacional | J34: Feriado Nacional
A35: =+B35 | B35: 46303 | C35: Examen Segunda Etapa | D35: =IFERROR(VLOOKUP(B35, fechaMEC, 3, FALSE), "Clase Normal") | H35: 46157 | I35: Día de la Independencia Nacional | J35: Dia para conmemorar
A36: =+B36 | B36: 46310 | D36: =IFERROR(VLOOKUP(B36, fechaMEC, 3, FALSE), "Clase Normal") | H36: 46171 | I36: Día del Ejército Paraguayo | J36: Dia para conmemorar
A37: =+B37 | B37: 46317 | D37: =IFERROR(VLOOKUP(B37, fechaMEC, 3, FALSE), "Clase Normal") | E37: =IFERROR(VLOOKUP(B37, fechaMEC, 2, FALSE), "Ejecutado") | H37: 46185 | I37: Paz del Chaco | J37: Feriado Nacional
A38: =+B38 | B38: 46324 | D38: =IFERROR(VLOOKUP(B38, fechaMEC, 3, FALSE), "Clase Normal") | H38: 46185 | I38: Paz del Chaco (Firma del Protocolo de Paz, 1935) | J38: Asueto - Departamental / Desfile
A39: =+B39 | B39: 46331 | D39: =IFERROR(VLOOKUP(B39, fechaMEC, 3, FALSE), "Clase Normal") | H39: 46192 | I39: Día del Árbol (En Paraguay) | J39: Clase Normal
A40: =+B40 | B40: 46338 | D40: =IFERROR(VLOOKUP(B40, fechaMEC, 3, FALSE), "Clase Normal") | H40: 46216 | I40: Inicio Vacaciones de Invierno | J40: MEC - VACACIONES
...

Sheet V1_03-ASISTENCIA
C2: PLANILLA DE ASISTENCIA | D2: =+AVERAGE(D4:D17) | I2: CIENCIAS NATURALES | O2: SEPTIMO | S2: TT | T2: 2026
A3: N° Orden | C3: Apellido/s Nombre/s | D3: % DE ASISTENCIA | E3: FIRMAS | F3: 46079 | G3: 46086 | H3: 46093 | I3: 46100 | J3: 46107 | K3: 46114 | L3: 46121 | M3: 46128 | N3: 46135 | O3: 46142 | P3: 46149 | Q3: 46156 | R3: 46163 | S3: 46170 | T3: 46177 | U3: 46184 | V3: 46191 | W3: 46198 | X3: 46205 | Y3: 46212 | Z3: 46219 | AA3: 46226 | AB3: 46233 | AC3: 46240 | AD3: 46247 | AE3: 46254 | AF3: 46261 | AG3: 46268 | AH3: 46275 | AI3: 46282 | AJ3: 46289 | AK3: 46296 | AL3: 46303 | AM3: 46310 | AN3: 46317 | AO3: 46324 | AP3: 46331 | AQ3: 46338 | AR3: 46345 | AS3: 46352 | EN3: =+TODAY()
A4: 1 | C4: =+'Datos '!H1 | D4: =_xlfn.LET(_xlpm.rango, F4:AJ4, (COUNTIF(_xlpm.rango, "P") + COUNTIF(_xlpm.rango, "PF")) / (COUNTIF(_xlpm.rango, "P") + COUNTIF(_xlpm.rango, "A") + COUNTIF(_xlpm.rango, "PF"))) | E4: =COUNTIF(F4:W4,"PF") | F4: P | G4: PF | H4: P | I4: PF | J4: P | K4: F | L4: PF | M4: PF | Q4: F | S4: P
A5: 2 | C5: =+'Datos '!H2 | D5: =_xlfn.LET(_xlpm.rango, F5:AJ5, (COUNTIF(_xlpm.rango, "P") + COUNTIF(_xlpm.rango, "PF")) / (COUNTIF(_xlpm.rango, "P") + COUNTIF(_xlpm.rango, "A") + COUNTIF(_xlpm.rango, "PF"))) | E5: =COUNTIF(F5:W5,"PF") | F5: P | G5: PF | H5: P | I5: PF | J5: P | K5: F | L5: PF | M5: P | Q5: F | S5: P
A6: 3 | C6: =+'Datos '!H3 | D6: =_xlfn.LET(_xlpm.rango, F6:AJ6, (COUNTIF(_xlpm.rango, "P") + COUNTIF(_xlpm.rango, "PF")) / (COUNTIF(_xlpm.rango, "P") + COUNTIF(_xlpm.rango, "A") + COUNTIF(_xlpm.rango, "PF"))) | E6: =COUNTIF(F6:W6,"PF") | F6: P | G6: PF | H6: P | I6: PF | J6: P | K6: F | L6: PF | M6: P | Q6: F | S6: P
A7: 4 | C7: =+'Datos '!H4 | D7: =_xlfn.LET(_xlpm.rango, F7:AJ7, (COUNTIF(_xlpm.rango, "P") + COUNTIF(_xlpm.rango, "PF")) / (COUNTIF(_xlpm.rango, "P") + COUNTIF(_xlpm.rango, "A") + COUNTIF(_xlpm.rango, "PF"))) | E7: =COUNTIF(F7:W7,"PF") | F7: P | G7: PF | H7: P | I7: PF | J7: P | K7: F | L7: PF | M7: PF | Q7: F | S7: P
A8: 5 | C8: =+'Datos '!H5 | D8: =_xlfn.LET(_xlpm.rango, F8:AJ8, (COUNTIF(_xlpm.rango, "P") + COUNTIF(_xlpm.rango, "PF")) / (COUNTIF(_xlpm.rango, "P") + COUNTIF(_xlpm.rango, "A") + COUNTIF(_xlpm.rango, "PF"))) | E8: =COUNTIF(F8:W8,"PF") | F8: P | G8: PF | H8: P | I8: PF | J8: P | K8: F | L8: PF | M8: PF | Q8: F | S8: P
A9: 6 | C9: =+'Datos '!H6 | D9: =_xlfn.LET(_xlpm.rango, F9:AJ9, (COUNTIF(_xlpm.rango, "P") + COUNTIF(_xlpm.rango, "PF")) / (COUNTIF(_xlpm.rango, "P") + COUNTIF(_xlpm.rango, "A") + COUNTIF(_xlpm.rango, "PF"))) | E9: =COUNTIF(F9:W9,"PF") | F9: P | G9: PF | H9: P | I9: PF | J9: P | K9: F | L9: PF | M9: P | Q9: F | S9: P
A10: 7 | C10: =+'Datos '!H7 | D10: =_xlfn.LET(_xlpm.rango, F10:AJ10, (COUNTIF(_xlpm.rango, "P") + COUNTIF(_xlpm.rango, "PF")) / (COUNTIF(_xlpm.rango, "P") + COUNTIF(_xlpm.rango, "A") + COUNTIF(_xlpm.rango, "PF"))) | E10: =COUNTIF(F10:W10,"PF") | F10: P | G10: PF | H10: P | I10: PF | J10: P | K10: F | L10: PF | M10: PF | Q10: F | S10: a
A11: 8 | C11: =+'Datos '!H8 | D11: =_xlfn.LET(_xlpm.rango, F11:AJ11, (COUNTIF(_xlpm.rango, "P") + COUNTIF(_xlpm.rango, "PF")) / (COUNTIF(_xlpm.rango, "P") + COUNTIF(_xlpm.rango, "A") + COUNTIF(_xlpm.rango, "PF"))) | E11: =COUNTIF(F11:W11,"PF") | F11: P | G11: PF | H11: P | I11: PF | J11: P | K11: F | L11: PF | M11: P | Q11: F | S11: aj
A12: 9 | B12: D | C12: =+'Datos '!H9 | D12: =_xlfn.LET(_xlpm.rango, F12:AJ12, (COUNTIF(_xlpm.rango, "P") + COUNTIF(_xlpm.rango, "PF")) / (COUNTIF(_xlpm.rango, "P") + COUNTIF(_xlpm.rango, "A") + COUNTIF(_xlpm.rango, "PF"))) | E12: =COUNTIF(F12:W12,"PF") | F12: P | G12: PF | H12: P | I12: PF | J12: P | K12: F | L12: PF | M12: PF | Q12: F | S12: P
A13: 10 | C13: =+'Datos '!H10 | D13: =_xlfn.LET(_xlpm.rango, F13:AJ13, (COUNTIF(_xlpm.rango, "P") + COUNTIF(_xlpm.rango, "PF")) / (COUNTIF(_xlpm.rango, "P") + COUNTIF(_xlpm.rango, "A") + COUNTIF(_xlpm.rango, "PF"))) | E13: =COUNTIF(F13:W13,"PF") | F13: P | G13: PF | H13: P | I13: PF | J13: P | K13: F | L13: PF | M13: PF | Q13: F | S13: P
A14: 11 | C14: =+'Datos '!H11 | D14: =_xlfn.LET(_xlpm.rango, F14:AJ14, (COUNTIF(_xlpm.rango, "P") + COUNTIF(_xlpm.rango, "PF")) / (COUNTIF(_xlpm.rango, "P") + COUNTIF(_xlpm.rango, "A") + COUNTIF(_xlpm.rango, "PF"))) | E14: =COUNTIF(F14:W14,"PF") | F14: P | G14: PF | H14: P | I14: PF | J14: P | K14: F | L14: PF | M14: PF | Q14: F | S14: P
A15: 12 | C15: =+'Datos '!H12 | D15: =_xlfn.LET(_xlpm.rango, F15:AJ15, (COUNTIF(_xlpm.rango, "P") + COUNTIF(_xlpm.rango, "PF")) / (COUNTIF(_xlpm.rango, "P") + COUNTIF(_xlpm.rango, "A") + COUNTIF(_xlpm.rango, "PF"))) | E15: =COUNTIF(F15:W15,"PF") | F15: P | G15: PF | H15: P | I15: PF | J15: P | K15: F | L15: PF | M15: PF | Q15: F | S15: P
A16: 13 | C16: =+'Datos '!H13 | D16: =_xlfn.LET(_xlpm.rango, F16:AJ16, (COUNTIF(_xlpm.rango, "P") + COUNTIF(_xlpm.rango, "PF")) / (COUNTIF(_xlpm.rango, "P") + COUNTIF(_xlpm.rango, "A") + COUNTIF(_xlpm.rango, "PF"))) | E16: =COUNTIF(F16:W16,"PF") | F16: P | G16: PF | H16: P | I16: PF | J16: P | K16: F | L16: PF | M16: P | Q16: F | S16: P
A17: 14 | C17: =+'Datos '!H14 | D17: =_xlfn.LET(_xlpm.rango, F17:AJ17, (COUNTIF(_xlpm.rango, "P") + COUNTIF(_xlpm.rango, "PF")) / (COUNTIF(_xlpm.rango, "P") + COUNTIF(_xlpm.rango, "A") + COUNTIF(_xlpm.rango, "PF"))) | E17: =COUNTIF(F17:W17,"PF") | F17: P | G17: PF | H17: P | I17: PF | J17: P | K17: F | L17: PF | M17: PFP | Q17: F | S17: P
A18: 15 | C18: ESTIGARRIBIA, ALISON | S18: a

Sheet V1_04-RSA
O1: Promoción de la Salud
A2: ID | B2: Nombre del Alumno | C2: - Identifica principios éticos y morales. | D2: - Diferencia moral y moralidad. | E2: - Reconoce problemáticas éticas globales. | F2: - Analiza causas de la mortalidad infantil. | G2: - Valora el código de convivencia. | H2: - Propone normas de respeto mutuo. | I2: - Define tipos de bullying. | J2: - Identifica consecuencias psicológicas. | K2: - Propone acciones de prevención. | L2: - Diferencia mediación de negociación. | M2: - Aplica pasos de la negociación asertiva. | N2: - Define el concepto de canasta básica. | O2: - Analiza el impacto de la pobreza. | P2: - Identifica tipos de violencia familiar. | Q2: - Conoce rutas de denuncia en Paraguay. | R2: - Explica la universalidad de los derechos. | S2: - Distingue progresividad de irreversibilidad. | T2: - Reconoce formas de explotación infantil. | U2: - Valora la protección contra el trabajo forzado. | V2: - Identifica factores de exclusión femenina. | W2: - Propone acciones para la igualdad. | X2: - Identifica la función tributaria. | Y2: - Valora la función social de los tributos. | Z2: - Reconoce funciones del Ministerio de Hacienda. | AA2: - Diferencia roles de Intendentes y Gobernadores.
A3: 1 | B3: =+'03-ASISTENCIA'!C3
A4: 2 | B4: =+'03-ASISTENCIA'!C4 | C4: 1 | D4: 1 | E4: 1 | H4: 1
A5: 3 | B5: =+'03-ASISTENCIA'!C5 | C5: 1 | D5: 1 | E5: 1 | H5: 1
A6: 4 | B6: =+'03-ASISTENCIA'!C6 | C6: 1 | D6: 1 | E6: 1 | H6: 1
A7: 5 | B7: =+'03-ASISTENCIA'!C7 | C7: 1 | D7: 1 | E7: 1 | H7: 1
A8: 6 | B8: =+'03-ASISTENCIA'!C8 | C8: 1 | D8: 1 | E8: 1 | H8: 1
A9: 7 | B9: =+'03-ASISTENCIA'!C9 | C9: 1 | D9: 1 | E9: 1 | H9: 1
A10: 8 | B10: =+'03-ASISTENCIA'!C10 | C10: 1 | D10: 1 | E10: 1 | H10: 1
A11: 9 | B11: =+'03-ASISTENCIA'!C11 | C11: 1 | D11: 1 | E11: 1 | H11: 1
A12: 10 | B12: =+'03-ASISTENCIA'!C12 | C12: 1 | D12: 1 | E12: 1 | H12: 1
A13: 11 | B13: =+'03-ASISTENCIA'!C13 | C13: 1 | D13: 1 | E13: 1 | H13: 1
A14: 12 | B14: =+'03-ASISTENCIA'!C14 | C14: 1 | D14: 1 | E14: 1 | H14: 1
A15: 13 | B15: =+'03-ASISTENCIA'!C15 | C15: 1 | D15: 1 | E15: 1 | H15: 1
... A17: 15 | B17: =+'03-ASISTENCIA'!C17 | C17: 1 | D17: 1 | E17: 1 | H17: 1

Sheet V1_05-BD-_CUADRO_ANECDOTICO
A1: Registro de Alumnos
B2: Fecha | C2: Alumno | D2: Situación | E2: Categoria | F2: Tipo de Indicador
B3: 46131 | C3: Nombre y Apellido | D3: Ale-06. Entrega tareas incompletas o descuidadas. | E3: =+VLOOKUP(D3,indicadores,3,0) | F3: =+VLOOKUP(D3,indicadores,4,0)
F4: =+VLOOKUP(D4,indicadores,4,0)
F5: =+VLOOKUP(D5,indicadores,4,0)
F6: =+VLOOKUP(D6,indicadores,4,0)
F7: =+VLOOKUP(D7,indicadores,4,0)
F8: =+VLOOKUP(D8,indicadores,4,0)
F9: =+VLOOKUP(D9,indicadores,4,0)
F10: =+VLOOKUP(D10,indicadores,4,0)
F11: =+VLOOKUP(D11,indicadores,4,0)
F12: =+VLOOKUP(D12,indicadores,4,0)

Sheet V1_Detalle1
A1: Detalles de . - Alumno : Nombre y Apellido, Categoria: Alerta/Mejora
A3: Fecha | B3: Alumno | C3: Situación | D3: Categoria | E3: Tipo de Indicador
A4: 46131 | B4: Nombre y Apellido | C4: Ale-06. Entrega tareas incompletas o descuidadas. | D4: Alerta/Mejora | E4: Académica

Sheet V1_05-RESUMEN_-CUADRO_ANECDOTIC
B3: Etiquetas de fila | C3: Cantidad de Reportes | E3: . | F3: .
B4: Alerta/Mejora | C4: 1 | E4: Etiquetas de fila | F4: Alerta/Mejora | G4: Total general
B5: Total general | C5: 1 | E5: Nombre y Apellido | F5: 1 | G5: 1
E6: Total general | F6: 1 | G6: 1
B8: Etiquetas de fila | C8: Tipo de Indicador.
B9: Total general
I12: 46136

Sheet V1_examen
A1: N° Orden | C1: Apellido/s Nombre/s | D1: GrupoS | E1: Suma | F1: Carpeta | G1: 1| El grupo se organizó adecuadamente.. | H1: 2| Los roles estuvieron claramente distribuidos.. | I1: 3| Todos asumieron responsabilidades.. | J1: 4| Todos los integrantes participaron.. | K1: 5| Existió respeto entre compañeros.. | L1: 6| Se observó compromiso grupal.. | M1: 7| El tema ético fue comprendido correctamente.. | N1: 8| La dramatización representó una situación ética clara.. | O1: 9| El contenido estuvo relacionado con valores y ciudadanía.. | P1: 10| La presentación fue creativa.. | Q1: 11| Utilizaron ambientación adecuada.. | R1: 12| El vestuario ayudó a representar la dramatización.. | S1: 13| Los estudiantes se expresaron con claridad.. | T1: 14| Respetaron el tiempo asignado.. | U1: 15| La reflexión final dejó una enseñanza ética.. | CW1: =+TODAY()
A2: 1 | C2: =+'Datos '!H1 | D2: G3 | E2: =+SUM(F2:U2) | F2: 1 | G2: 1 | H2: 1 | I2: 1 | J2: 1 | K2: 1 | L2: 1 | M2: 1 | N2: 1 | O2: 1 | P2: 1 | Q2: 1 | R2: 0 | S2: 1 | T2: 0 | U2: 1
A3: 2 | C3: =+'Datos '!H2 | D3: G1 | E3: =+SUM(F3:U3) | F3: 1
A4: 3 | C4: =+'Datos '!H3 | D4: G2 | E4: =+SUM(F4:U4) | F4: 1 | G4: 1 | H4: 1 | I4: 1 | J4: 1 | K4: 1 | L4: 1 | M4: 1 | N4: 1 | O4: 1 | P4: 1 | Q4: 1 | R4: 1 | S4: 1 | T4: 1 | U4: 1
A5: 4 | C5: =+'Datos '!H4 | D5: G2 | E5: =+SUM(F5:U5) | F5: 1 | G5: 1 | H5: 1 | I5: 1 | J5: 1 | K5: 1 | L5: 1 | M5: 1 | N5: 1 | O5: 1 | P5: 1 | Q5: 1 | R5: 1 | S5: 1 | T5: 1 | U5: 1
A6: 5 | C6: =+'Datos '!H5 | D6: G3 | E6: =+SUM(F6:U6) | F6: 1 | G6: 1 | H6: 1 | I6: 1 | J6: 1 | K6: 1 | L6: 1 | M6: 1 | N6: 1 | O6: 1 | P6: 1 | Q6: 1 | R6: 0 | S6: 1 | T6: 0 | U6: 1
A7: 6 | C7: =+'Datos '!H6 | D7: NO EXISTE | E7: =+SUM(F7:U7) | F7: 0
A8: 7 | C8: =+'Datos '!H7 | D8: G3 | E8: =+SUM(F8:U8) | F8: 1 | G8: A | H8: 1 | I8: 1 | M8: n
A9: 8 | C9: =+'Datos '!H8 | D9: G1 | E9: =+SUM(F9:U9) | F9: 1
A10: 9 | B10: D | C10: =+'Datos '!H9 | D10: G3 | E10: =+SUM(F10:U10) | F10: 1 | G10: 1 | H10: 1 | I10: 1 | J10: 1 | K10: 1 | L10: 1 | M10: 1 | N10: 1 | O10: 1 | P10: 1 | Q10: 1 | R10: 0 | S10: 1 | T10: 0 | U10: 1
A11: 10 | C11: =+'Datos '!H10 | D11: G2 | E11: =+SUM(F11:U11) | F11: 1 | G11: A | H11: 1 | I11: 1 | J11: 1 | K11: 1 | L11: 1 | M11: 1 | N11: 1 | O11: 1 | P11: 1 | Q11: 1 | R11: 1 | S11: 1 | T11: 1 | U11: 1
A12: 11 | C12: =+'Datos '!H11 | D12: G3 | E12: =+SUM(F12:U12) | F12: 1 | G12: 1 | H12: 1 | I12: 1 | J12: 1 | K12: 1 | L12: 1 | M12: 1 | N12: 1 | O12: 1 | P12: 1 | Q12: 1 | R12: 0 | S12: 1 | T12: 0 | U12: 1
A13: 12 | C13: =+'Datos '!H12 | D13: G2 | E13: =+SUM(F13:U13) | F13: 1 | G13: 1 | H13: 1 | I13: 1 | J13: 1 | K13: 1 | L13: 1 | M13: 1 | N13: 1 | O13: 1 | P13: 1 | Q13: 1 | R13: 1 | S13: 1 | T13: 1 | U13: 1
A14: 13 | C14: =+'Datos '!H13 | D14: G2 | E14: =+SUM(F14:U14) | F14: 1 | G14: 1 | H14: 1 | I14: 1 | J14: 1 | K14: 1 | L14: 1 | M14: 1 | N14: 1 | O14: 1 | P14: 1 | Q14: 1 | R14: 1 | S14: 1 | T14: 1 | U14: 1
A15: 14 | C15: =+'Datos '!H14 | D15: G1 | E15: =+SUM(F15:U15) | F15: 1 | G15: A

Sheet V1_06-PROCESO
C2: PLANILLA DE ASISTENCIA | D2: =+AVERAGE(D5:D18) | H2: CIENCIAS NATURALES | N2: SEPTIMO | R2: TT | S2: 2026
A4: N° Orden | C4: Apellido/s Nombre/s | D4: % DE ASISTENCIA | E4: FIRMAS | F4: =+'04-RSA'!C2 | G4: =+'04-RSA'!D2 | H4: =+'04-RSA'!E2 | I4: =+'04-RSA'!F2 | J4: =+'04-RSA'!G2 | K4: =+'04-RSA'!H2 | L4: =+'04-RSA'!I2 | M4: =+'04-RSA'!J2 | ... AH4: =+'04-RSA'!AE2 | EL4: =+TODAY()
A5: 1 | C5: =+'Datos '!B2 | D5: =+'03-ASISTENCIA'!D4 | E5: =+'03-ASISTENCIA'!E4 | F5: 1 | G5: 1 | H5: 1 | I5: 1 | J5: 1 | K5: 1
A6: 2 | C6: =+'Datos '!B3 | D6: =+'03-ASISTENCIA'!D5 | E6: =+'03-ASISTENCIA'!E5 | F6: 1 | G6: 1 | H6: 1 | I6: 1 | J6: 1 | K6: 1
A7: 3 | C7: =+'Datos '!B4 | D7: =+'03-ASISTENCIA'!D6 | E7: =+'03-ASISTENCIA'!E6 | F7: 1 | G7: 1 | H7: 1 | I7: 1 | J7: 1 | K7: 1
A8: 4 | C8: =+'Datos '!B5 | D8: =+'03-ASISTENCIA'!D7 | E8: =+'03-ASISTENCIA'!E7 | F8: 1 | G8: 1 | H8: 1 | I8: 1 | J8: 1 | K8: 1
A9: 5 | C9: =+'Datos '!B6 | D9: =+'03-ASISTENCIA'!D8 | E9: =+'03-ASISTENCIA'!E8 | F9: 1 | G9: 1 | H9: 1 | I9: 1 | J9: 1 | K9: 1
A10: 6 | C10: =+'Datos '!B7 | D10: =+'03-ASISTENCIA'!D9 | E10: =+'03-ASISTENCIA'!E9 | F10: 1 | G10: 1 | H10: 1 | I10: 1 | J10: 1 | K10: 1
A11: 7 | C11: =+'Datos '!B8 | D11: =+'03-ASISTENCIA'!D10 | E11: =+'03-ASISTENCIA'!E10 | F11: 1 | G11: 1 | H11: 1 | I11: 1 | J11: 1 | K11: 1
A12: 8 | C12: =+'Datos '!B9 | D12: =+'03-ASISTENCIA'!D11 | E12: =+'03-ASISTENCIA'!E11 | F12: 1 | G12: 1 | H12: 1 | I12: 1 | J12: 1 | K12: 1
A13: 9 | B13: D | C13: =+'Datos '!B10 | D13: =+'03-ASISTENCIA'!D12 | E13: =+'03-ASISTENCIA'!E12 | F13: 1 | G13: 1 | H13: 1 | I13: 1 | J13: 1 | K13: 1
A14: 10 | C14: =+'Datos '!B11 | D14: =+'03-ASISTENCIA'!D13 | E14: =+'03-ASISTENCIA'!E13 | F14: 1 | G14: 1 | H14: 1 | I14: 1 | J14: 1 | K14: 1
A15: 11 | C15: =+'Datos '!B12 | D15: =+'03-ASISTENCIA'!D14 | E15: =+'03-ASISTENCIA'!E14 | F15: 1 | G15: 1 | H15: 1 | I15: 1 | J15: 1 | K15: 1
A16: 12 | C16: =+'Datos '!B13 | D16: =+'03-ASISTENCIA'!D15 | E16: =+'03-ASISTENCIA'!E15 | F16: 1 | G16: 1 | H16: 1 | I16: 1 | J16: 1 | K16: 1
A17: 13 | C17: =+'Datos '!B14 | D17: =+'03-ASISTENCIA'!D16 | E17: =+'03-ASISTENCIA'!E16 | F17: 1 | G17: 1 | H17: 1 | I17: 1 | J17: 1 | K17: 1
A18: 14 | C18: =+'Datos '!B15 | D18: =+'03-ASISTENCIA'!D17 | E18: =+'03-ASISTENCIA'!E17 | F18: 1 | G18: 1 | H18: 1 | I18: 1 | J18: 1 | K18: 1

Sheet V1_07-CALENDARIO_MEC
A1: Fecha (DD/MM/YYYY) | B1: Evento / Conmemoración | C1: Tipo
A2: 46023 | B2: Año Nuevo | C2: Feriado Nacional
A3: 46063 | B3: Apertura Institucional y Retorno Docente | C3: MEC - INSTITUCIONAL
A4: 46076 | B4: Inicio de Clases (Sector Oficial) | C4: MEC - INSTITUCIONAL
A5: 46077 | B5: Día de la Mujer Paraguaya (Homenaje a las Residentas) | C5: Dia para conmemorar
A6: 46082 | B6: Día de los Héroes | C6: Feriado Nacional
A7: 46082 | B7: Día de los Héroes (Muerte del Mcal. López en Cerro Corá) | C7: Dia para conmemorar
A8: 46102 | B8: Día Mundial de la Poesía y Día del Síndrome de Down | C8: Dia para conmemorar
A9: 46114 | B9: Jueves Santo (Receso) | C9: Feriado Nacional
A10: 46115 | B10: Viernes Santo (Receso) | C10: Feriado Nacional
A11: 46135 | B11: Día del Libro y del Derecho de Autor | C11: Dia para conmemorar
A12: 46138 | B12: Día del Periodista (Muerte de Santiago Leguizamón) | C12: Dia para conmemorar
A13: 46142 | B13: Día del Maestro (En Paraguay) | C13: Dia para conmemorar
... A52: 46381 | B52: Navidad | C52: Feriado Nacional

Sheet V1_08-_INDICADORES_AC
B1: Indicador | C1: Indicador | D1: Tipo de Indicador | E1: Categoría
B2: =+CONCATENATE(LEFT(D2,3),"-",C2) | C2: 02. Presenta lagunas en conocimientos previos. | D2: Alerta/Mejora | E2: Académica
B3: =+CONCATENATE(LEFT(D3,3),"-",C3) | C3: 04. Se limita a memorizar sin comprender. | D3: Alerta/Mejora | E3: Académica
B4: =+CONCATENATE(LEFT(D4,3),"-",C4) | C4: 06. Entrega tareas incompletas o descuidadas. | D4: Alerta/Mejora | E4: Académica
B5: =+CONCATENATE(LEFT(D5,3),"-",C5) | C5: 08. Se bloquea ante desafíos matemáticos. | D5: Alerta/Mejora | E5: Académica
B6: =+CONCATENATE(LEFT(D6,3),"-",C6) | C6: 10. Tiene dificultades de expresión oral/escrita. | D6: Alerta/Mejora | E6: Académica
B7: =+CONCATENATE(LEFT(D7,3),"-",C7) | C7: 12. Muestra rechazo o desinterés por la lectura. | D7: Alerta/Mejora | E7: Académica
B8: =+CONCATENATE(LEFT(D8,3),"-",C8) | C8: 14. Requiere supervisión constante para avanzar. | D8: Alerta/Mejora | E8: Académica
B9: =+CONCATENATE(LEFT(D9,3),"-",C9) | C9: 16. Muestra apatía por temas nuevos. | D9: Alerta/Mejora | E9: Académica
B10: =+CONCATENATE(LEFT(D10,3),"-",C10) | C10: 18. Desafía activamente la autoridad. | D10: Alerta/Mejora | E10: Conductual
B11: =+CONCATENATE(LEFT(D11,3),"-",C11) | C11: 20. Presenta retardos o inasistencias frecuentes. | D11: Alerta/Mejora | E11: Conductual
B12: =+CONCATENATE(LEFT(D12,3),"-",C12) | C12: 22. Daña el mobiliario o materiales escolares. | D12: Alerta/Mejora | E12: Conductual
B13: =+CONCATENATE(LEFT(D13,3),"-",C13) | C13: 24. Interrumpe constantemente el flujo de clase. | D13: Alerta/Mejora | E13: Conductual
... B52: =+CONCATENATE(LEFT(D52,3),"-",C52) | C52: 49. Acepta retroalimentación constructiva. | D52: Fortaleza/Logro | E52: Actitudinal

Sheet V1_Hoja4

Sheet V1_09.Diagnostico
A1: Categoría | B1: Indicador | C1: Indicador | D1: Tipo de Indicador | E1: Cantidad de veces | F1: NOTA | G1: =+'Datos '!G14
A2: Académica | B2: =+CONCATENATE(LEFT(D2,3),"-",C2) | C2: 02. Presenta lagunas en conocimientos previos. | D2: Alerta/Mejora | E2: 3 | F2: =VLOOKUP(G2, $I$3:$K$7, 3, 1) | G2: =+G$1-E2
A3: Académica | B3: =+CONCATENATE(LEFT(D3,3),"-",C3) | C3: 04. Se limita a memorizar sin comprender. | D3: Alerta/Mejora | E3: 3 | F3: =VLOOKUP(G3, $I$3:$K$7, 3, 1) | G3: =+G$1-E3 | I3: 1 | J3: 8 | K3: 1 | M3: Etiquetas de fila | N3: Suma de Cantidad de veces
A4: Académica | B4: =+CONCATENATE(LEFT(D4,3),"-",C4) | C4: 06. Entrega tareas incompletas o descuidadas. | D4: Alerta/Mejora | E4: 2 | F4: =VLOOKUP(G4, $I$3:$K$7, 3, 1) | G4: =+G$1-E4 | J4: 9 | K4: 2 | M4: Alerta/Mejora | N4: 89
A5: Académica | B5: =+CONCATENATE(LEFT(D5,3),"-",C5) | C5: 08. Se bloquea ante desafíos matemáticos. | D5: Alerta/Mejora | E5: 3 | F5: =VLOOKUP(G5, $I$3:$K$7, 3, 1) | G5: =+G$1-E5 | I5: 10 | J5: 11 | K5: 3 | M5: Fortaleza/Logro | N5: 588
A6: Académica | B6: =+CONCATENATE(LEFT(D6,3),"-",C6) | C6: 10. Tiene dificultades de expresión oral/escrita. | D6: Alerta/Mejora | E6: 2 | F6: =VLOOKUP(G6, $I$3:$K$7, 3, 1) | G6: =+G$1-E6 | I6: 12 | J6: 13 | K6: 4 | M6: Total general | N6: 677
A7: Académica | B7: =+CONCATENATE(LEFT(D7,3),"-",C7) | C7: 12. Muestra rechazo o desinterés por la lectura. | D7: Alerta/Mejora | E7: 3 | F7: =VLOOKUP(G7, $I$3:$K$7, 3, 1) | G7: =+G$1-E7 | J7: 14 | K7: 5
A8: Académica | B8: =+CONCATENATE(LEFT(D8,3),"-",C8) | C8: 14. Requiere supervisión constante para avanzar. | D8: Alerta/Mejora | E8: 3 | F8: =VLOOKUP(G8, $I$3:$K$7, 3, 1) | G8: =+G$1-E8
A9: Académica | B9: =+CONCATENATE(LEFT(D9,3),"-",C9) | C9: 16. Muestra apatía por temas nuevos. | D9: Alerta/Mejora | E9: 0 | F9: =VLOOKUP(G9, $I$3:$K$7, 3, 1) | G9: =+G$1-E9
A10: Conductual | B10: =+CONCATENATE(LEFT(D10,3),"-",C10) | C10: 18. Desafía activamente la autoridad. | D10: Alerta/Mejora | E10: 0 | F10: =VLOOKUP(G10, $I$3:$K$7, 3, 1) | G10: =+G$1-E10
A11: Conductual | B11: =+CONCATENATE(LEFT(D11,3),"-",C11) | C11: 20. Presenta retardos o inasistencias frecuentes. | D11: Alerta/Mejora | E11: 2 | F11: =VLOOKUP(G11, $I$3:$K$7, 3, 1) | G11: =+G$1-E11
A12: Conductual | B12: =+CONCATENATE(LEFT(D12,3),"-",C12) | C12: 22. Daña el mobiliario o materiales escolares. | D12: Alerta/Mejora | E12: 0 | F12: =VLOOKUP(G12, $I$3:$K$7, 3, 1) | G12: =+G$1-E12
A13: Conductual | B13: =+CONCATENATE(LEFT(D13,3),"-",C13) | C13: 24. Interrumpe constantemente el flujo de clase. | D13: Alerta/Mejora | E13: 2 | F13: =VLOOKUP(G13, $I$3:$K$7, 3, 1) | G13: =+G$1-E13
A14: Conductual | B14: =+CONCATENATE(LEFT(D14,3),"-",C14) | C14: 26. Emplea lenguaje soez o despectivo. | D14: Alerta/Mejora | E14: 0 | F14: =VLOOKUP(G14, $I$3:$K$7, 3, 1) | G14: =+G$1-E14
A15: Conductual | B15: =+CONCATENATE(LEFT(D15,3),"-",C15) | C15: 28. Miente o culpa a otros por sus actos. | D15: Alerta/Mejora | E15: 0 | F15: =VLOOKUP(G15, $I$3:$K$7, 3, 1) | G15: =+G$1-E15
A16: Conductual | B16: =+CONCATENATE(LEFT(D16,3),"-",C16) | C16: 30. Se distrae con dispositivos electrónicos. | D16: Alerta/Mejora | E16: 0 | F16: =VLOOKUP(G16, $I$3:$K$7, 3, 1) | G16: =+G$1-E16
A17: Conductual | B17: =+CONCATENATE(LEFT(D17,3),"-",C17) | C17: 32. Fomenta el desorden o el caos en el grupo. | D17: Alerta/Mejora | E17: 0 | F17: =VLOOKUP(G17, $I$3:$K$7, 3, 1) | G17: =+G$1-E17
A18: Socio-Emocional | B18: =+CONCATENATE(LEFT(D18,3),"-",C18) | C18: 34. Se rinde fácilmente ante la frustración. | D18: Alerta/Mejora | E18: 2 | F18: =VLOOKUP(G18, $I$3:$K$7, 3, 1) | G18: =+G$1-E18
A19: Socio-Emocional | B19: =+CONCATENATE(LEFT(D19,3),"-",C19) | C19: 36. Trabaja de forma aislada o es individualista. | D19: Alerta/Mejora | E19: 1 | F19: =VLOOKUP(G19, $I$3:$K$7, 3, 1) | G19: =+G$1-E19
... A26: Actitudinal | B26: =+CONCATENATE(LEFT(D26,3),"-",C26) | C26: 50. Se muestra a la defensiva ante críticas. | D26: Alerta/Mejora | E26: 0 | F26: =VLOOKUP(G26, $I$3:$K$7, 3, 1) | G26: =+G$1-E26
A28: Académica | B28: =+CONCATENATE(LEFT(D28,3),"-",C28) | C28: 01. Domina los conceptos clave del grado. | D28: Fortaleza/Logro | E28: 12 | F28: =VLOOKUP(G28, $I$3:$K$7, 3, 1) | G28: =+E28
A29: Académica | B29: =+CONCATENATE(LEFT(D29,3),"-",C29) | C29: 03. Posee un pensamiento crítico y analítico. | D29: Fortaleza/Logro | E29: 14 | F29: =VLOOKUP(G29, $I$3:$K$7, 3, 1) | G29: =+E29
A30: Académica | B30: =+CONCATENATE(LEFT(D30,3),"-",C30) | C30: 05. Entrega trabajos con alta calidad y orden. | D30: Fortaleza/Logro | E30: 12 | F30: =VLOOKUP(G30, $I$3:$K$7, 3, 1) | G30: =+E30
A31: Académica | B31: =+CONCATENATE(LEFT(D31,3),"-",C31) | C31: 07. Resuelve problemas lógicos con fluidez. | D31: Fortaleza/Logro | E31: 12 | F31: =VLOOKUP(G31, $I$3:$K$7, 3, 1) | G31: =+E31
A32: Académica | B32: =+CONCATENATE(LEFT(D32,3),"-",C32) | C32: 09. Utiliza vocabulario técnico preciso. | D32: Fortaleza/Logro | E32: 12 | F32: =VLOOKUP(G32, $I$3:$K$7, 3, 1) | G32: =+E32
A33: Académica | B33: =+CONCATENATE(LEFT(D33,3),"-",C33) | C33: 11. Posee excelentes hábitos de lectura. | D33: Fortaleza/Logro | E33: 11 | F33: =VLOOKUP(G33, $I$3:$K$7, 3, 1) | G33: =+E33
A34: Académica | B34: =+CONCATENATE(LEFT(D34,3),"-",C34) | C34: 13. Es autónomo en la realización de tareas. | D34: Fortaleza/Logro | E34: 14 | F34: =VLOOKUP(G34, $I$3:$K$7, 3, 1) | G34: =+E34
A35: Académica | B35: =+CONCATENATE(LEFT(D35,3),"-",C35) | C35: 15. Investiga más allá de lo solicitado. | D35: Fortaleza/Logro | E35: 12 | F35: =VLOOKUP(G35, $I$3:$K$7, 3, 1) | G35: =+E35
A36: Conductual | B36: =+CONCATENATE(LEFT(D36,3),"-",C36) | C36: 17. Respeta las normas de convivencia. | D36: Fortaleza/Logro | E36: 14 | F36: =VLOOKUP(G36, $I$3:$K$7, 3, 1) | G36: =+E36
A37: Conductual | B37: =+CONCATENATE(LEFT(D37,3),"-",C37) | C37: 19. Es puntual en todas sus obligaciones. | D37: Fortaleza/Logro | E37: 12 | F37: =VLOOKUP(G37, $I$3:$K$7, 3, 1) | G37: =+E37
A38: Conductual | B38: =+CONCATENATE(LEFT(D38,3),"-",C38) | C38: 21. Cuida el material propio y ajeno. | D38: Fortaleza/Logro | E38: 14 | F38: =VLOOKUP(G38, $I$3:$K$7, 3, 1) | G38: =+E38
A39: Conductual | B39: =+CONCATENATE(LEFT(D39,3),"-",C39) | C39: 23. Escucha con atención y no interrumpe. | D39: Fortaleza/Logro | E39: 14 | F39: =VLOOKUP(G39, $I$3:$K$7, 3, 1) | G39: =+E39
A40: Conductual | B40: =+CONCATENATE(LEFT(D40,3),"-",C40) | C40: 25. Utiliza el lenguaje de forma respetuosa. | D40: Fortaleza/Logro | E40: 14 | F40: =VLOOKUP(G40, $I$3:$K$7, 3, 1) | G40: =+E40
A41: Conductual | B41: =+CONCATENATE(LEFT(D41,3),"-",C41) | C41: 27. Reconoce sus errores honestamente. | D41: Fortaleza/Logro | E41: 14 | F41: =VLOOKUP(G41, $I$3:$K$7, 3, 1) | G41: =+E41 | K41: Suma de Cantidad de veces | L41: Etiquetas de columna
A42: Conductual | B42: =+CONCATENATE(LEFT(D42,3),"-",C42) | C42: 29. Usa la tecnología con fines educativos. | D42: Fortaleza/Logro | E42: 12 | F42: =VLOOKUP(G42, $I$3:$K$7, 3, 1) | G42: =+E42 | K42: Etiquetas de fila | L42: Alerta/Mejora | M42: Fortaleza/Logro | N42: Total general
A43: Conductual | B43: =+CONCATENATE(LEFT(D43,3),"-",C43) | C43: 31. Mantiene el orden en espacios comunes. | D43: Fortaleza/Logro | E43: 11 | F43: =VLOOKUP(G43, $I$3:$K$7, 3, 1) | G43: =+E43 | K43: Académica | L43: 28 | M43: 90 | N43: 118
A44: Socio-Emocional | B44: =+CONCATENATE(LEFT(D44,3),"-",C44) | C44: 33. Muestra resiliencia ante el fracaso. | D44: Fortaleza/Logro | E44: 12 | F44: =VLOOKUP(G44, $I$3:$K$7, 3, 1) | G44: =+E44 | K44: Actitudinal | L44: 8 | M44: 97 | N44: 105
A45: Socio-Emocional | B45: =+CONCATENATE(LEFT(D45,3),"-",C45) | C45: 35. Trabaja de forma colaborativa y equitativa. | D45: Fortaleza/Logro | E45: 12 | F45: =VLOOKUP(G45, $I$3:$K$7, 3, 1) | G45: =+E45 | K45: Conductual | L45: 33 | M45: 239 | N45: 272
A46: Socio-Emocional | B46: =+CONCATENATE(LEFT(D46,3),"-",C46) | C46: 37. Es empático con las necesidades ajenas. | D46: Fortaleza/Logro | E46: 12 | F46: =VLOOKUP(G46, $I$3:$K$7, 3, 1) | G46: =+E46 | K46: Socio-Emocional | L46: 20 | M46: 162 | N46: 182
A47: Socio-Emocional | B47: =+CONCATENATE(LEFT(D47,3),"-",C47) | C47: 39. Posee un liderazgo positivo y ético. | D47: Fortaleza/Logro | E47: 12 | F47: =VLOOKUP(G47, $I$3:$K$7, 3, 1) | G47: =+E47 | K47: Total general | L47: 89 | M47: 588 | N47: 677
...

Sheet V1_Escala
A1: COLEGIO SAGRADA FAMILIA
A2: ESCALA DE CALIFICACIONES - 60%
A4: 15 Puntos | B4: 16 Puntos | C4: 17 Puntos | D4: 18 Puntos | E4: 19 Puntos | F4: 20 Puntos | G4: 21 Puntos | H4: 22 Puntos
A5: 0 - 9 = 1 | B5: 0 - 9 = 1 | C5: 0 - 10 = 1 | D5: 0 - 10 = 1 | E5: 0 - 10 = 1 | F5: 0 - 11 = 1 | G5: 0 - 12 = 1 | H5: 0 - 13 = 1
A6: 9 - 10 = 2 | B6: 9 - 10 = 2 | C6: 11 - 12 = 2 | D6: 11 - 12 = 2 | E6: 11 - 12 = 2 | F6: 12 - 13 = 2 | G6: 13 - 14 = 2 | H6: 14 - 15 = 2
A7: 11 - 12 = 3 | B7: 11 - 12 = 3 | C7: 13 - 14 = 3 | D7: 13 - 14 = 3 | E7: 13 - 15 = 3 | F7: 14 - 16 = 3 | G7: 15 - 17 = 3 | H7: 16 - 18 = 3
A8: 13 - 14 = 4 | B8: 13 - 14 = 4 | C8: 15 - 16 = 4 | D8: 15 - 16 = 4 | E8: 16 - 17 = 4 | F8: 17 - 18 = 4 | G8: 18 - 19 = 4 | H8: 19 - 20 = 4
A9: 15 = 5 | B9: 15 - 16 = 5 | C9: 17 = 5 | D9: 17 - 18 = 5 | E9: 18 - 19 = 5 | F9: 19 - 20 = 5 | G9: 20 - 21 = 5 | H9: 21 - 22 = 5
A11: 23 Puntos | B11: 24 Puntos | C11: 25 Puntos | D11: 26 Puntos | E11: 27 Puntos | F11: 28 Puntos | G11: 29 Puntos | H11: 30 Puntos
A12: 0 - 13 = 1 | B12: 0 - 13 = 1 | C12: 0 - 14 = 1 | D12: 0 - 15 = 1 | E12: 0 - 15 = 1 | F12: 0 - 16 = 1 | G12: 0 - 17 = 1 | H12: 0 - 17 = 1
A13: 14 - 15 = 2 | B13: 14 - 16 = 2 | C13: 15 - 17 = 2 | D13: 16 - 18 = 2 | E13: 16 - 18 = 2 | F13: 17 - 19 = 2 | G13: 18 - 20 = 2 | H13: 18 - 20 = 2
A14: 16 - 18 = 3 | B14: 17 - 19 = 3 | C14: 18 - 20 = 3 | D14: 19 - 21 = 3 | E14: 19 - 21 = 3 | F14: 20 - 22 = 3 | G14: 21 - 23 = 3 | H14: 21 - 24 = 3
A15: 19 - 21 = 4 | B15: 20 - 22 = 4 | C15: 21 - 23 = 4 | D15: 22 - 24 = 4 | E15: 22 - 24 = 4 | F15: 23 - 25 = 4 | G15: 24 - 26 = 4 | H15: 25 - 27 = 4
A16: 22 - 23 = 5 | B16: 23 - 24 = 5 | C16: 24 - 25 = 5 | D16: 25 - 26 = 5 | E16: 25 - 27 = 5 | F16: 26 - 28 = 5 | G16: 27 - 29 = 5 | H16: 28 - 30 = 5
... A51: 58 - 63 = 5 | B51: 59 - 64 = 5 | C51: 60 - 65 = 5 | D51: 61 - 66 = 5 | E51: 61 - 67 = 5 | F51: 62 - 68 = 5 | G51: 63 - 69 = 5 | H51: 64 - 70 = 5
A56: COLEGIO SAGRADA FAMILIA
A57: ESCALA DE CALIFICACIONES - 60%
A59: 71 Puntos | B59: 72 Puntos | C59: 73 Puntos | D59: 74 Puntos | E59: 75 Puntos | F59: 76 Puntos | G59: 77 Puntos | H59: 78 Puntos
A60: 0 - 42 = 1 | B60: 0 - 42 = 1 | C60: 0 - 43 = 1 | D60: 0 - 43 = 1 | E60: 0 - 44 = 1 | F60: 0 - 45 = 1 | G60: 0 - 45 = 1 | H60: 0 - 46 = 1
A61: 43 - 49 = 2 | B61: 43 - 49 = 2 | C61: 44 - 50 = 2 | D61: 44 - 51 = 2 | E61: 45 - 52 = 2 | F61: 46 - 53 = 2 | G61: 46 - 53 = 2 | H61: 47 - 54 = 2
A62: 50 - 57 = 3 | B62: 50 - 57 = 3 | C62: 51 - 58 = 3 | D62: 52 - 59 = 3 | E62: 53 - 60 = 3 | F62: 54 - 61 = 3 | G62: 54 - 61 = 3 | H62: 55 - 62 = 3
A63: 58 - 64 = 4 | B63: 58 - 65 = 4 | C63: 59 - 66 = 4 | D63: 60 - 67 = 4 | E63: 61 - 68 = 4 | F63: 62 - 69 = 4 | G63: 62 - 69 = 4 | H63: 63 - 70 = 4
A64: 65 - 71 = 5 | B64: 66 - 72 = 5 | C64: 67 - 73 = 5 | D64: 68 - 74 = 5 | E64: 69 - 75 = 5 | F64: 70 - 76 = 5 | G64: 70 - 77 = 5 | H64: 71 - 78 = 5
A66: 79 Puntos | B66: 80 Puntos | C66: 81 Puntos | D66: 82 Puntos | E66: 83 Puntos | F66: 84 Puntos | G66: 85 Puntos | H66: 86 Puntos
A67: 0 - 46 = 1 | B67: 0 - 47 = 1 | C67: 0 - 48 = 1 | D67: 0 - 48 = 1 | E67: 0 - 48 = 1 | F67: 0 - 49 = 1 | G67: 0 - 50 = 1 | H67: 0 - 51 = 1
A68: 47 - 54 = 2 | B68: 48 - 55 = 2 | C68: 49 - 56 = 2 | D68: 49 - 56 = 2 | E68: 49 - 57 = 2 | F68: 50 - 58 = 2 | G68: 51 - 59 = 2 | H68: 52 - 60 = 2
A69: 55 - 63 = 3 | B69: 56 - 64 = 3 | C69: 57 - 65 = 3 | D69: 57 - 65 = 3 | E69: 58 - 66 = 3 | F69: 59 - 67 = 3 | G69: 60 - 68 = 3 | H69: 61 - 69 = 3
A70: 64 - 71 = 4 | B70: 65 - 72 = 4 | C70: 66 - 73 = 4 | D70: 66 - 74 = 4 | E70: 67 - 75 = 4 | F70: 68 - 76 = 4 | G70: 69 - 77 = 4 | H70: 70 - 78 = 4
A71: 72 - 79 = 5 | B71: 73 - 80 = 5 | C71: 74 - 81 = 5 | D71: 75 - 82 = 5 | E71: 76 - 83 = 5 | F71: 77 - 84 = 5 | G71: 78 - 85 = 5 | H71: 79 - 86 = 5
... A106: 108-119= 5 | B106: 109-120= 5 | C106: 110-121= 5 | D106: 111-122= 5 | E106: 112-123= 5 | F106: 113-124= 5 | G106: 114-125= 5 | H106: 115-126= 5

Sheet V1_Datos
A1: Nombre completo | B1: Nombre y Apellido | G1: 1 | H1: ACOSTA FERREIRA, FRANCO JESUS
A2: =+H1 | B2: =TRIM(LEFT(MID(A2, FIND(",", A2) + 1, LEN(A2)), FIND(" ", TRIM(MID(A2, FIND(",", A2) + 1, LEN(A2)))))) & " " & LEFT(A2, FIND(" ", A2) - 1) | G2: 2 | H2: ARCE GAONA, NAOMI JOSELIN
A3: =+H2 | B3: =TRIM(LEFT(MID(A3, FIND(",", A3) + 1, LEN(A3)), FIND(" ", TRIM(MID(A3, FIND(",", A3) + 1, LEN(A3)))))) & " " & LEFT(A3, FIND(" ", A3) - 1) | G3: 3 | H3: ARZAMENDIA GONZALEZ, GUSTAVO ASAEL DEJESUS
A4: =+H3 | B4: =TRIM(LEFT(MID(A4, FIND(",", A4) + 1, LEN(A4)), FIND(" ", TRIM(MID(A4, FIND(",", A4) + 1, LEN(A4)))))) & " " & LEFT(A4, FIND(" ", A4) - 1) | G4: 4 | H4: AYALA MALDONADO, MIGUEL PETROVIC
A5: =+H4 | B5: =TRIM(LEFT(MID(A5, FIND(",", A5) + 1, LEN(A5)), FIND(" ", TRIM(MID(A5, FIND(",", A5) + 1, LEN(A5)))))) & " " & LEFT(A5, FIND(" ", A5) - 1) | G5: 5 | H5: BENITEZ OVELAR, LUNA ARAMI
A6: =+H5 | B6: =TRIM(LEFT(MID(A6, FIND(",", A6) + 1, LEN(A6)), FIND(" ", TRIM(MID(A6, FIND(",", A6) + 1, LEN(A6)))))) & " " & LEFT(A6, FIND(" ", A6) - 1) | G6: 6 | H6: BENITEZ, LURDES ESMERALDA
A7: =+H6 | B7: =TRIM(LEFT(MID(A7, FIND(",", A7) + 1, LEN(A7)), FIND(" ", TRIM(MID(A7, FIND(",", A7) + 1, LEN(A7)))))) & " " & LEFT(A7, FIND(" ", A7) - 1) | G7: 7 | H7: DURE OVIEDO, MYLAN DANILO
A8: =+H7 | B8: =TRIM(LEFT(MID(A8, FIND(",", A8) + 1, LEN(A8)), FIND(" ", TRIM(MID(A8, FIND(",", A8) + 1, LEN(A8)))))) & " " & LEFT(A8, FIND(" ", A8) - 1) | G8: 8 | H8: FERREIRA CACERES, PAULA JAZMIN
A9: =+H8 | B9: =TRIM(LEFT(MID(A9, FIND(",", A9) + 1, LEN(A9)), FIND(" ", TRIM(MID(A9, FIND(",", A9) + 1, LEN(A9)))))) & " " & LEFT(A9, FIND(" ", A9) - 1) | G9: 9 | H9: GIMENEZ AMARILLA, JOSE MARIA
A10: =+H9 | B10: =TRIM(LEFT(MID(A10, FIND(",", A10) + 1, LEN(A10)), FIND(" ", TRIM(MID(A10, FIND(",", A10) + 1, LEN(A10)))))) & " " & LEFT(A10, FIND(" ", A10) - 1) | G10: 10 | H10: LEGUIZAMON INSAURRALDE, ANGEL NAHUEL
A11: =+H10 | B11: =TRIM(LEFT(MID(A11, FIND(",", A11) + 1, LEN(A11)), FIND(" ", TRIM(MID(A11, FIND(",", A11) + 1, LEN(A11)))))) & " " & LEFT(A11, FIND(" ", A11) - 1) | G11: 11 | H11: MILLAN BAEZ, GIOVANNA MAILEN
A12: =+H11 | B12: =TRIM(LEFT(MID(A12, FIND(",", A12) + 1, LEN(A12)), FIND(" ", TRIM(MID(A12, FIND(",", A12) + 1, LEN(A12)))))) & " " & LEFT(A12, FIND(" ", A12) - 1) | G12: 12 | H12: RAMIREZ ALFONSO, NELSON DANIEL
A13: =+H12 | B13: =TRIM(LEFT(MID(A13, FIND(",", A13) + 1, LEN(A13)), FIND(" ", TRIM(MID(A13, FIND(",", A13) + 1, LEN(A13)))))) & " " & LEFT(A13, FIND(" ", A13) - 1) | G13: 13 | H13: SILVA SERVIN, EMMANUEL EZEKIEL
A14: =+H13 | B14: =TRIM(LEFT(MID(A14, FIND(",", A14) + 1, LEN(A14)), FIND(" ", TRIM(MID(A14, FIND(",", A14) + 1, LEN(A14)))))) & " " & LEFT(A14, FIND(" ", A14) - 1) | G14: 14 | H14: VILLASANTI SALDIVAR ,GENESIS ABIGAIL
A15: =+H14 | B15: =TRIM(LEFT(MID(A15, FIND(",", A15) + 1, LEN(A15)), FIND(" ", TRIM(MID(A15, FIND(",", A15) + 1, LEN(A15)))))) & " " & LEFT(A15, FIND(" ", A15) - 1)

Sheet V2_Prinicipal
A1: INSTITUCION | G1: Promedio de Asistencia
A2: ESC.EXC. Manuel | D2: Dias de clase | E2: Viernes | G2: =+'03-ASISTENCIA'!D2
A3: Molinas | D3: Horas ingreso | E3: 0.54166667
D4: Hora salida | E4: 0.63194444
A5: GRADO | D5: Receso | E5: 0.010416667
A6: SEPTIMO | D6: Horas cátedras | E6: =+(E4-E3)*3600/(40*60)-E5
A8: TURNO | D8: INTRUMENTOS | J8: Plan Unidad 1
A9: TARDE | C9: 1 | D9: PLAN ANUAL | J9: Plan Unidad 2
C10: 2 | D10: REGISTRO DE TEMAS | J10: Plan Unidad 3
A11: ASIGNATURA | C11: 3 | D11: ASISTENCIA | J11: Plan Unidad 4
A12: FORMACIÓN ETICA | C12: 4 | D12: RSA | J12: Plan Unidad 5
C13: 5 | D13: CUADRO ANECDOTICO | J13: Plan Unidad 6
A14: PROFESOR | D14: INSTITUCIONAL | J14: Plan Unidad 7
A15: CHRISTHIAN KEIM | C15: 6 | D15: POA 2026 | J15: Plan Unidad 8
C16: 7 | D16: POA 2026 - ASIGNATURA | J16: Plan Unidad 9
A17: 2026 | C17: 8 | D17: CALENDARIO MEC | J17: Plan Unidad 10
C18: 9 | D18: PROYECTOS INSTITUCIONALES
C19: 10 | D19: INDICADORES ACTITUDINALES
C20: 11 | D20: DIAGNOSTICO

Sheet V2_01-PLAN_ANUAL
A1: Unidad Temática | B1: Capacidades | C1: Contenido | D1: Estrategias Didácticas | E1: Indicadores | F1: Estrategias evaluativas | G1: Recursos Didácticos
A2: Persona y entorno | B2: Reflexiona acerca de la práctica de los principios y valores democráticos. | C2: Ética y Moral. Diferencias y moralidad social. | D2: - Responde preguntas. | E2: - Identifica principios éticos y morales. | F2: - Portafolio de trabajo. | G2: - Cuadernillo Serie Poty.
A3: Persona y entorno | B3: Reflexiona acerca de la práctica de los principios y valores democráticos. | C3: Ética y Moral. Diferencias y moralidad social. | D3: - Establece diferencias entre ética y moral. | E3: - Diferencia moral y moralidad. | F3: - RSA con indicadores. | G3: - Cartulinas y pinceles.
A4: Persona y entorno | B4: Reflexiona acerca de la práctica de los principios y valores democráticos. | C4: Ética y Moral. Diferencias y moralidad social. | D4: - Diseña carteles de concientización.
A5: Persona y entorno | B5: Analiza dilemas éticos contemporáneos y su impacto social. | C5: **Escándalos éticos de nuestro tiempo:** Pobreza, hambre y mortalidad infantil. | D5: - Análisis de noticias actuales. | E5: - Reconoce problemáticas éticas globales. | F5: - Registro de observación. | G5: - Material de lectura.
A6: Persona y entorno | B6: Analiza dilemas éticos contemporáneos y su impacto social. | C6: **Escándalos éticos de nuestro tiempo:** Pobreza, hambre y mortalidad infantil. | D6: - Debate sobre déficit de agua potable. | E6: - Analiza causas de la mortalidad infantil. | F6: - Ensayos escritos. | G6: - Artículos de prensa.
A7: Persona y entorno | B7: Analiza dilemas éticos contemporáneos y su impacto social. | C7: **Escándalos éticos de nuestro tiempo:** Pobreza, hambre y mortalidad infantil. | D7: - Elaboración de ensayos breves.
A8: Persona y entorno | B8: Comprende la importancia de la convivencia armónica en el ámbito escolar. | C8: **Acuerdos de relacionamiento:** Código de convivencia docente-estudiante. | D8: - Lluvia de ideas sobre normas. | E8: - Valora el código de convivencia. | F8: - Participación activa. | G8: - Papelógrafos.
A9: Persona y entorno | B9: Comprende la importancia de la convivencia armónica en el ámbito escolar. | C9: **Acuerdos de relacionamiento:** Código de convivencia docente-estudiante. | D9: - Redacción participativa de acuerdos de aula. | E9: - Propone normas de respeto mutuo. | F9: - Documento de acuerdos. | G9: - Marcadores.
A10: Persona y entorno | B10: Identifica situaciones de acoso escolar y propone medidas de prevención. | C10: Bullying: Concepto, tipos, causas y consecuencias. | D10: (Abordaje > 2 horas) | E10: - Define tipos de bullying. | F10: - Guía de trabajo grupal. | G10: - Proyector / Videos.
A11: Persona y entorno | B11: Identifica situaciones de acoso escolar y propone medidas de prevención. | C11: Bullying: Concepto, tipos, causas y consecuencias. | D11: - Cine debate sobre casos reales. | E11: - Identifica consecuencias psicológicas.
A12: Persona y entorno | B12: Identifica situaciones de acoso escolar y propone medidas de prevención. | C12: Bullying: Concepto, tipos, causas y consecuencias. | D12: - Talleres de rol (agresor/víctima). | E12: - Propone acciones de prevención. | F12: - RSA. | G12: - Fichas de casos.
A13: Persona y entorno | B13: Identifica situaciones de acoso escolar y propone medidas de prevención. | C13: Bullying: Concepto, tipos, causas y consecuencias. | D13: - Elaboración de protocolos de ayuda.
A14: Persona y entorno | B14: Aplica técnicas básicas de resolución de conflictos en situaciones cotidianas. | C14: Mediación, Negociación y Confrontación. | D14: (Abordaje > 2 horas) | E14: - Diferencia mediación de negociación. | F14: - Evaluación de desempeño (Role-play). | G14: - Guiones de casos.
A15: Persona y entorno | B15: Aplica técnicas básicas de resolución de conflictos en situaciones cotidianas. | C15: Mediación, Negociación y Confrontación. | D15: - Simulacros de mediación escolar.
A16: Persona y entorno | B16: Aplica técnicas básicas de resolución de conflictos en situaciones cotidianas. | C16: Mediación, Negociación y Confrontación. | D16: - Ejercicios de comunicación asertiva. | E16: - Aplica pasos de la negociación asertiva. | G16: - Pizarra.
A17: Persona y entorno | B17: Aplica técnicas básicas de resolución de conflictos en situaciones cotidianas. | C17: Mediación, Negociación y Confrontación. | D17: - Análisis de casos de conflicto.
A18: La Familia | B18: Analiza la situación socioeconómica de las familias paraguayas. | C18: Pobreza y Canasta Básica Familiar. | D18: - Investigación de precios actuales. | E18: - Define el concepto de canasta básica. | F18: - Informe de investigación. | G18: - Datos estadísticos.
A19: La Familia | B19: Analiza la situación socioeconómica de las familias paraguayas. | C19: Pobreza y Canasta Básica Familiar. | D19: - Comparación de ingresos y costos básicos. | E19: - Analiza el impacto de la pobreza. | F19: - Cuadro comparativo. | G19: - Calculadora.
A20: La Familia | B20: Reconoce factores que inciden en la violencia intrafamiliar. | C20: Violencia Intrafamiliar: Causas y prevención. | D20: (Abordaje > 2 horas) | E20: - Identifica tipos de violencia familiar. | F20: - Cuestionario reflexivo. | G20: - Trípticos informativos.
A21: La Familia | B21: Reconoce factores que inciden en la violencia intrafamiliar. | C21: Violencia Intrafamiliar: Causas y prevención. | D21: - Charla con especialistas o videos informativos. | E21: - Conoce rutas de denuncia en Paraguay. | F21: - RSA. | G21: - Proyector.
A22: La Familia | B22: Reconoce factores que inciden en la violencia intrafamiliar. | C22: Violencia Intrafamiliar: Causas y prevención. | D22: - Análisis de la Ley contra violencia doméstica.
A23: La Familia | B23: Reconoce factores que inciden en la violencia intrafamiliar. | C23: Violencia Intrafamiliar: Causas y prevención. | D23: - Mapa de instituciones de denuncia.
A24: Derechos Humanos | B24: Reconoce los principios básicos que rigen los Derechos Humanos. | C24: Principios de los DD.HH.: Universalidad, progresividad e irreversibilidad. | D24: (Abordaje > 2 horas) | E24: - Explica la universalidad de los derechos. | F24: - Mapa conceptual. | G24: - Constitución Nacional.
A25: Derechos Humanos | B25: Reconoce los principios básicos que rigen los Derechos Humanos. | C25: Principios de los DD.HH.: Universalidad, progresividad e irreversibilidad. | D25: - Lectura comprensiva de la Declaración Universal.
A26: Derechos Humanos | B26: Reconoce los principios básicos que rigen los Derechos Humanos. | C26: Principios de los DD.HH.: Universalidad, progresividad e irreversibilidad. | D26: - Análisis de casos históricos. | E26: - Distingue progresividad de irreversibilidad. | F26: - Prueba escrita formativa. | G26: - Textos guía.
A27: Derechos Humanos | B27: Reconoce los principios básicos que rigen los Derechos Humanos. | C27: Principios de los DD.HH.: Universalidad, progresividad e irreversibilidad. | D27: - Debate sobre la temporalidad de los derechos.
A28: Derechos Humanos | B28: Analiza situaciones de vulneración de derechos en la niñez y adolescencia. | C28: **Causas de explotación:** Sexual, laboral y trabajos forzados. | D28: - Análisis de estadísticas nacionales. | E28: - Reconoce formas de explotación infantil. | F28: - Murales preventivos. | G28: - Afiches.
A29: Derechos Humanos | B29: Analiza situaciones de vulneración de derechos en la niñez y adolescencia. | C29: **Causas de explotación:** Sexual, laboral y trabajos forzados. | D29: - Identificación de señales de riesgo. | E29: - Valora la protección contra el trabajo forzado. | F29: - Portafolio. | G29: - Material audiovisual.
A30: Derechos Humanos | B30: Analiza situaciones de vulneración de derechos en la niñez y adolescencia. | C30: **Causas de explotación:** Sexual, laboral y trabajos forzados. | D30: - Elaboración de campañas preventivas.
A31: Democracia y Estado | B31: Analiza la situación de la mujer en la estructura social actual. | C31: **Pobreza, desigualdad y exclusión a la mujer.** | D31: - Debate sobre brecha salarial y acceso a educación. | E31: - Identifica factores de exclusión femenina. | F31: - RSA. | G31: - Material de lectura.
A32: Democracia y Estado | B32: Analiza la situación de la mujer en la estructura social actual. | C32: **Pobreza, desigualdad y exclusión a la mujer.** | D32: - Biografías de mujeres líderes en Paraguay. | E32: - Propone acciones para la igualdad. | F32: - Debate dirigido. | G32: - Artículos de género.
